[Sat Dec 04 20:37:41.525635 2021] [wsgi:error] [pid 4777:tid 140385016239872] [remote 192.168.1.237:48702] mod_wsgi (pid=4777): Target WSGI script '/var/www/mainapp/mainapp/mainapp.wsgi' cannot be loaded as Python module.
[Sat Dec 04 20:37:41.525686 2021] [wsgi:error] [pid 4777:tid 140385016239872] [remote 192.168.1.237:48702] mod_wsgi (pid=4777): Exception occurred processing WSGI script '/var/www/mainapp/mainapp/mainapp.wsgi'.
[Sat Dec 04 20:37:41.543410 2021] [wsgi:error] [pid 4777:tid 140385016239872] [remote 192.168.1.237:48702] Traceback (most recent call last):
[Sat Dec 04 20:37:41.543453 2021] [wsgi:error] [pid 4777:tid 140385016239872] [remote 192.168.1.237:48702]   File "/var/www/mainapp/mainapp/mainapp.wsgi", line 5, in <module>
[Sat Dec 04 20:37:41.543458 2021] [wsgi:error] [pid 4777:tid 140385016239872] [remote 192.168.1.237:48702]     with open(activate_this) as file_:
[Sat Dec 04 20:37:41.543477 2021] [wsgi:error] [pid 4777:tid 140385016239872] [remote 192.168.1.237:48702] PermissionError: [Errno 13] Permission denied: '/home/server/.local/share/virtualenvs/mainapp-c6pGQO_3/bin/activate_this.py'
[Sat Dec 04 20:46:02.039900 2021] [wsgi:error] [pid 4777:tid 140384982652672] [remote 127.0.0.1:55874] mod_wsgi (pid=4777): Target WSGI script '/var/www/mainapp/mainapp/mainapp.wsgi' cannot be loaded as Python module.
[Sat Dec 04 20:46:02.039942 2021] [wsgi:error] [pid 4777:tid 140384982652672] [remote 127.0.0.1:55874] mod_wsgi (pid=4777): Exception occurred processing WSGI script '/var/www/mainapp/mainapp/mainapp.wsgi'.
[Sat Dec 04 20:46:02.040062 2021] [wsgi:error] [pid 4777:tid 140384982652672] [remote 127.0.0.1:55874] Traceback (most recent call last):
[Sat Dec 04 20:46:02.040079 2021] [wsgi:error] [pid 4777:tid 140384982652672] [remote 127.0.0.1:55874]   File "/var/www/mainapp/mainapp/mainapp.wsgi", line 6, in <module>
[Sat Dec 04 20:46:02.040083 2021] [wsgi:error] [pid 4777:tid 140384982652672] [remote 127.0.0.1:55874]     with open(activate_this) as file_:
[Sat Dec 04 20:46:02.040093 2021] [wsgi:error] [pid 4777:tid 140384982652672] [remote 127.0.0.1:55874] PermissionError: [Errno 13] Permission denied: '/home/server/.local/share/virtualenvs/mainapp-c6pGQO_3/bin/activate_this.py'
[Sat Dec 04 20:50:15.307707 2021] [wsgi:error] [pid 5052:tid 140385016239872] [remote 127.0.0.1:55984] mod_wsgi (pid=5052): Target WSGI script '/var/www/mainapp/mainapp/mainapp.wsgi' cannot be loaded as Python module.
[Sat Dec 04 20:50:15.307754 2021] [wsgi:error] [pid 5052:tid 140385016239872] [remote 127.0.0.1:55984] mod_wsgi (pid=5052): Exception occurred processing WSGI script '/var/www/mainapp/mainapp/mainapp.wsgi'.
[Sat Dec 04 20:50:15.311085 2021] [wsgi:error] [pid 5052:tid 140385016239872] [remote 127.0.0.1:55984] Traceback (most recent call last):
[Sat Dec 04 20:50:15.311106 2021] [wsgi:error] [pid 5052:tid 140385016239872] [remote 127.0.0.1:55984]   File "/var/www/mainapp/mainapp/mainapp.wsgi", line 6, in <module>
[Sat Dec 04 20:50:15.311110 2021] [wsgi:error] [pid 5052:tid 140385016239872] [remote 127.0.0.1:55984]     with open(activate_this) as file_:
[Sat Dec 04 20:50:15.311122 2021] [wsgi:error] [pid 5052:tid 140385016239872] [remote 127.0.0.1:55984] PermissionError: [Errno 13] Permission denied: '/home/server/.local/share/virtualenvs/mainapp-c6pGQO_3/bin/activate_this.py'
[Sat Dec 04 20:50:16.074883 2021] [wsgi:error] [pid 5052:tid 140384982652672] [remote 127.0.0.1:55986] mod_wsgi (pid=5052): Target WSGI script '/var/www/mainapp/mainapp/mainapp.wsgi' cannot be loaded as Python module.
[Sat Dec 04 20:50:16.074927 2021] [wsgi:error] [pid 5052:tid 140384982652672] [remote 127.0.0.1:55986] mod_wsgi (pid=5052): Exception occurred processing WSGI script '/var/www/mainapp/mainapp/mainapp.wsgi'.
[Sat Dec 04 20:50:16.074983 2021] [wsgi:error] [pid 5052:tid 140384982652672] [remote 127.0.0.1:55986] Traceback (most recent call last):
[Sat Dec 04 20:50:16.075003 2021] [wsgi:error] [pid 5052:tid 140384982652672] [remote 127.0.0.1:55986]   File "/var/www/mainapp/mainapp/mainapp.wsgi", line 6, in <module>
[Sat Dec 04 20:50:16.075007 2021] [wsgi:error] [pid 5052:tid 140384982652672] [remote 127.0.0.1:55986]     with open(activate_this) as file_:
[Sat Dec 04 20:50:16.075026 2021] [wsgi:error] [pid 5052:tid 140384982652672] [remote 127.0.0.1:55986] PermissionError: [Errno 13] Permission denied: '/home/server/.local/share/virtualenvs/mainapp-c6pGQO_3/bin/activate_this.py'
[Sat Dec 04 20:59:26.338992 2021] [wsgi:error] [pid 5052:tid 140385016239872] [remote 192.168.1.237:48960] mod_wsgi (pid=5052): Target WSGI script '/var/www/mainapp/mainapp/mainapp.wsgi' cannot be loaded as Python module.
[Sat Dec 04 20:59:26.339126 2021] [wsgi:error] [pid 5052:tid 140385016239872] [remote 192.168.1.237:48960] mod_wsgi (pid=5052): Exception occurred processing WSGI script '/var/www/mainapp/mainapp/mainapp.wsgi'.
[Sat Dec 04 20:59:26.339592 2021] [wsgi:error] [pid 5052:tid 140385016239872] [remote 192.168.1.237:48960] Traceback (most recent call last):
[Sat Dec 04 20:59:26.339671 2021] [wsgi:error] [pid 5052:tid 140385016239872] [remote 192.168.1.237:48960]   File "/var/www/mainapp/mainapp/mainapp.wsgi", line 6, in <module>
[Sat Dec 04 20:59:26.339691 2021] [wsgi:error] [pid 5052:tid 140385016239872] [remote 192.168.1.237:48960]     with open(activate_this) as file_:
[Sat Dec 04 20:59:26.339738 2021] [wsgi:error] [pid 5052:tid 140385016239872] [remote 192.168.1.237:48960] PermissionError: [Errno 13] Permission denied: '/home/server/.local/share/virtualenvs/mainapp-c6pGQO_3/bin/activate_this.py'
[Sat Dec 04 20:59:26.360914 2021] [wsgi:error] [pid 5052:tid 140384982652672] [remote 192.168.1.237:48962] mod_wsgi (pid=5052): Target WSGI script '/var/www/mainapp/mainapp/mainapp.wsgi' cannot be loaded as Python module.
[Sat Dec 04 20:59:26.360963 2021] [wsgi:error] [pid 5052:tid 140384982652672] [remote 192.168.1.237:48962] mod_wsgi (pid=5052): Exception occurred processing WSGI script '/var/www/mainapp/mainapp/mainapp.wsgi'.
[Sat Dec 04 20:59:26.361068 2021] [wsgi:error] [pid 5052:tid 140384982652672] [remote 192.168.1.237:48962] Traceback (most recent call last):
[Sat Dec 04 20:59:26.361088 2021] [wsgi:error] [pid 5052:tid 140384982652672] [remote 192.168.1.237:48962]   File "/var/www/mainapp/mainapp/mainapp.wsgi", line 6, in <module>
[Sat Dec 04 20:59:26.361092 2021] [wsgi:error] [pid 5052:tid 140384982652672] [remote 192.168.1.237:48962]     with open(activate_this) as file_:
[Sat Dec 04 20:59:26.361105 2021] [wsgi:error] [pid 5052:tid 140384982652672] [remote 192.168.1.237:48962] PermissionError: [Errno 13] Permission denied: '/home/server/.local/share/virtualenvs/mainapp-c6pGQO_3/bin/activate_this.py'
[Sat Dec 04 21:01:48.295750 2021] [wsgi:error] [pid 5309:tid 140385007847168] [remote 192.168.1.237:48998] mod_wsgi (pid=5309): Target WSGI script '/var/www/mainapp/mainapp/mainapp.wsgi' cannot be loaded as Python module.
[Sat Dec 04 21:01:48.295792 2021] [wsgi:error] [pid 5309:tid 140385007847168] [remote 192.168.1.237:48998] mod_wsgi (pid=5309): Exception occurred processing WSGI script '/var/www/mainapp/mainapp/mainapp.wsgi'.
[Sat Dec 04 21:01:48.298896 2021] [wsgi:error] [pid 5309:tid 140385007847168] [remote 192.168.1.237:48998] Traceback (most recent call last):
[Sat Dec 04 21:01:48.298917 2021] [wsgi:error] [pid 5309:tid 140385007847168] [remote 192.168.1.237:48998]   File "/var/www/mainapp/mainapp/mainapp.wsgi", line 6, in <module>
[Sat Dec 04 21:01:48.298922 2021] [wsgi:error] [pid 5309:tid 140385007847168] [remote 192.168.1.237:48998]     with open(activate_this) as file_:
[Sat Dec 04 21:01:48.298933 2021] [wsgi:error] [pid 5309:tid 140385007847168] [remote 192.168.1.237:48998] PermissionError: [Errno 13] Permission denied: '/home/server/.local/share/virtualenvs/mainapp-c6pGQO_3/bin/activate_this.py'
[Sat Dec 04 21:01:49.116089 2021] [wsgi:error] [pid 5309:tid 140384982652672] [remote 192.168.1.237:49000] mod_wsgi (pid=5309): Target WSGI script '/var/www/mainapp/mainapp/mainapp.wsgi' cannot be loaded as Python module.
[Sat Dec 04 21:01:49.116127 2021] [wsgi:error] [pid 5309:tid 140384982652672] [remote 192.168.1.237:49000] mod_wsgi (pid=5309): Exception occurred processing WSGI script '/var/www/mainapp/mainapp/mainapp.wsgi'.
[Sat Dec 04 21:01:49.116187 2021] [wsgi:error] [pid 5309:tid 140384982652672] [remote 192.168.1.237:49000] Traceback (most recent call last):
[Sat Dec 04 21:01:49.116205 2021] [wsgi:error] [pid 5309:tid 140384982652672] [remote 192.168.1.237:49000]   File "/var/www/mainapp/mainapp/mainapp.wsgi", line 6, in <module>
[Sat Dec 04 21:01:49.116208 2021] [wsgi:error] [pid 5309:tid 140384982652672] [remote 192.168.1.237:49000]     with open(activate_this) as file_:
[Sat Dec 04 21:01:49.116218 2021] [wsgi:error] [pid 5309:tid 140384982652672] [remote 192.168.1.237:49000] PermissionError: [Errno 13] Permission denied: '/home/server/.local/share/virtualenvs/mainapp-c6pGQO_3/bin/activate_this.py'
[Sat Dec 04 21:08:16.474145 2021] [wsgi:error] [pid 5484:tid 140385016239872] [remote 192.168.1.237:49008] mod_wsgi (pid=5484): Target WSGI script '/var/www/mainapp/mainapp/mainapp.wsgi' cannot be loaded as Python module.
[Sat Dec 04 21:08:16.474193 2021] [wsgi:error] [pid 5484:tid 140385016239872] [remote 192.168.1.237:49008] mod_wsgi (pid=5484): Exception occurred processing WSGI script '/var/www/mainapp/mainapp/mainapp.wsgi'.
[Sat Dec 04 21:08:16.477457 2021] [wsgi:error] [pid 5484:tid 140385016239872] [remote 192.168.1.237:49008] Traceback (most recent call last):
[Sat Dec 04 21:08:16.477480 2021] [wsgi:error] [pid 5484:tid 140385016239872] [remote 192.168.1.237:49008]   File "/var/www/mainapp/mainapp/mainapp.wsgi", line 6, in <module>
[Sat Dec 04 21:08:16.477484 2021] [wsgi:error] [pid 5484:tid 140385016239872] [remote 192.168.1.237:49008]     with open(activate_this) as file_:
[Sat Dec 04 21:08:16.477496 2021] [wsgi:error] [pid 5484:tid 140385016239872] [remote 192.168.1.237:49008] PermissionError: [Errno 13] Permission denied: '/home/server/.local/share/virtualenvs/mainapp-c6pGQO_3/bin/activate_this.py'
[Sat Dec 04 21:08:17.487318 2021] [wsgi:error] [pid 5484:tid 140384982652672] [remote 192.168.1.237:49010] mod_wsgi (pid=5484): Target WSGI script '/var/www/mainapp/mainapp/mainapp.wsgi' cannot be loaded as Python module.
[Sat Dec 04 21:08:17.487359 2021] [wsgi:error] [pid 5484:tid 140384982652672] [remote 192.168.1.237:49010] mod_wsgi (pid=5484): Exception occurred processing WSGI script '/var/www/mainapp/mainapp/mainapp.wsgi'.
[Sat Dec 04 21:08:17.487414 2021] [wsgi:error] [pid 5484:tid 140384982652672] [remote 192.168.1.237:49010] Traceback (most recent call last):
[Sat Dec 04 21:08:17.487431 2021] [wsgi:error] [pid 5484:tid 140384982652672] [remote 192.168.1.237:49010]   File "/var/www/mainapp/mainapp/mainapp.wsgi", line 6, in <module>
[Sat Dec 04 21:08:17.487434 2021] [wsgi:error] [pid 5484:tid 140384982652672] [remote 192.168.1.237:49010]     with open(activate_this) as file_:
[Sat Dec 04 21:08:17.487445 2021] [wsgi:error] [pid 5484:tid 140384982652672] [remote 192.168.1.237:49010] PermissionError: [Errno 13] Permission denied: '/home/server/.local/share/virtualenvs/mainapp-c6pGQO_3/bin/activate_this.py'
[Sat Dec 04 21:14:03.204075 2021] [wsgi:error] [pid 5484:tid 140385016239872] [remote 192.168.1.237:49020] mod_wsgi (pid=5484): Target WSGI script '/var/www/mainapp/mainapp/mainapp.wsgi' cannot be loaded as Python module.
[Sat Dec 04 21:14:03.204117 2021] [wsgi:error] [pid 5484:tid 140385016239872] [remote 192.168.1.237:49020] mod_wsgi (pid=5484): Exception occurred processing WSGI script '/var/www/mainapp/mainapp/mainapp.wsgi'.
[Sat Dec 04 21:14:03.204176 2021] [wsgi:error] [pid 5484:tid 140385016239872] [remote 192.168.1.237:49020] Traceback (most recent call last):
[Sat Dec 04 21:14:03.204194 2021] [wsgi:error] [pid 5484:tid 140385016239872] [remote 192.168.1.237:49020]   File "/var/www/mainapp/mainapp/mainapp.wsgi", line 6, in <module>
[Sat Dec 04 21:14:03.204198 2021] [wsgi:error] [pid 5484:tid 140385016239872] [remote 192.168.1.237:49020]     with open(activate_this) as file_:
[Sat Dec 04 21:14:03.204209 2021] [wsgi:error] [pid 5484:tid 140385016239872] [remote 192.168.1.237:49020] PermissionError: [Errno 13] Permission denied: '/home/server/.local/share/virtualenvs/mainapp-c6pGQO_3/bin/activate_this.py'
[Sat Dec 04 21:14:03.979511 2021] [wsgi:error] [pid 5484:tid 140384982652672] [remote 192.168.1.237:49022] mod_wsgi (pid=5484): Target WSGI script '/var/www/mainapp/mainapp/mainapp.wsgi' cannot be loaded as Python module.
[Sat Dec 04 21:14:03.979545 2021] [wsgi:error] [pid 5484:tid 140384982652672] [remote 192.168.1.237:49022] mod_wsgi (pid=5484): Exception occurred processing WSGI script '/var/www/mainapp/mainapp/mainapp.wsgi'.
[Sat Dec 04 21:14:03.979600 2021] [wsgi:error] [pid 5484:tid 140384982652672] [remote 192.168.1.237:49022] Traceback (most recent call last):
[Sat Dec 04 21:14:03.979617 2021] [wsgi:error] [pid 5484:tid 140384982652672] [remote 192.168.1.237:49022]   File "/var/www/mainapp/mainapp/mainapp.wsgi", line 6, in <module>
[Sat Dec 04 21:14:03.979621 2021] [wsgi:error] [pid 5484:tid 140384982652672] [remote 192.168.1.237:49022]     with open(activate_this) as file_:
[Sat Dec 04 21:14:03.979631 2021] [wsgi:error] [pid 5484:tid 140384982652672] [remote 192.168.1.237:49022] PermissionError: [Errno 13] Permission denied: '/home/server/.local/share/virtualenvs/mainapp-c6pGQO_3/bin/activate_this.py'
[Sat Dec 04 21:15:01.851297 2021] [wsgi:error] [pid 5608:tid 140385016239872] [remote 192.168.1.237:49024] mod_wsgi (pid=5608): Target WSGI script '/var/www/mainapp/mainapp/mainapp.wsgi' cannot be loaded as Python module.
[Sat Dec 04 21:15:01.851345 2021] [wsgi:error] [pid 5608:tid 140385016239872] [remote 192.168.1.237:49024] mod_wsgi (pid=5608): Exception occurred processing WSGI script '/var/www/mainapp/mainapp/mainapp.wsgi'.
[Sat Dec 04 21:15:01.854800 2021] [wsgi:error] [pid 5608:tid 140385016239872] [remote 192.168.1.237:49024] Traceback (most recent call last):
[Sat Dec 04 21:15:01.854823 2021] [wsgi:error] [pid 5608:tid 140385016239872] [remote 192.168.1.237:49024]   File "/var/www/mainapp/mainapp/mainapp.wsgi", line 6, in <module>
[Sat Dec 04 21:15:01.854828 2021] [wsgi:error] [pid 5608:tid 140385016239872] [remote 192.168.1.237:49024]     with open(activate_this) as file_:
[Sat Dec 04 21:15:01.854840 2021] [wsgi:error] [pid 5608:tid 140385016239872] [remote 192.168.1.237:49024] PermissionError: [Errno 13] Permission denied: '/home/server/.local/share/virtualenvs/mainapp-c6pGQO_3/bin/activate_this.py'
[Sat Dec 04 21:15:02.760153 2021] [wsgi:error] [pid 5608:tid 140384991053568] [remote 192.168.1.237:49026] mod_wsgi (pid=5608): Target WSGI script '/var/www/mainapp/mainapp/mainapp.wsgi' cannot be loaded as Python module.
[Sat Dec 04 21:15:02.760195 2021] [wsgi:error] [pid 5608:tid 140384991053568] [remote 192.168.1.237:49026] mod_wsgi (pid=5608): Exception occurred processing WSGI script '/var/www/mainapp/mainapp/mainapp.wsgi'.
[Sat Dec 04 21:15:02.760276 2021] [wsgi:error] [pid 5608:tid 140384991053568] [remote 192.168.1.237:49026] Traceback (most recent call last):
[Sat Dec 04 21:15:02.760321 2021] [wsgi:error] [pid 5608:tid 140384991053568] [remote 192.168.1.237:49026]   File "/var/www/mainapp/mainapp/mainapp.wsgi", line 6, in <module>
[Sat Dec 04 21:15:02.760325 2021] [wsgi:error] [pid 5608:tid 140384991053568] [remote 192.168.1.237:49026]     with open(activate_this) as file_:
[Sat Dec 04 21:15:02.760336 2021] [wsgi:error] [pid 5608:tid 140384991053568] [remote 192.168.1.237:49026] PermissionError: [Errno 13] Permission denied: '/home/server/.local/share/virtualenvs/mainapp-c6pGQO_3/bin/activate_this.py'
[Sat Dec 04 21:15:49.745122 2021] [wsgi:error] [pid 5608:tid 140385016239872] [remote 192.168.1.237:49034] mod_wsgi (pid=5608): Target WSGI script '/var/www/mainapp/mainapp/mainapp.wsgi' cannot be loaded as Python module.
[Sat Dec 04 21:15:49.745177 2021] [wsgi:error] [pid 5608:tid 140385016239872] [remote 192.168.1.237:49034] mod_wsgi (pid=5608): Exception occurred processing WSGI script '/var/www/mainapp/mainapp/mainapp.wsgi'.
[Sat Dec 04 21:15:49.745247 2021] [wsgi:error] [pid 5608:tid 140385016239872] [remote 192.168.1.237:49034] Traceback (most recent call last):
[Sat Dec 04 21:15:49.745265 2021] [wsgi:error] [pid 5608:tid 140385016239872] [remote 192.168.1.237:49034]   File "/var/www/mainapp/mainapp/mainapp.wsgi", line 6, in <module>
[Sat Dec 04 21:15:49.745277 2021] [wsgi:error] [pid 5608:tid 140385016239872] [remote 192.168.1.237:49034]     with open(activate_this) as file_:
[Sat Dec 04 21:15:49.745288 2021] [wsgi:error] [pid 5608:tid 140385016239872] [remote 192.168.1.237:49034] PermissionError: [Errno 13] Permission denied: '/home/server/.local/share/virtualenvs/mainapp-c6pGQO_3/bin/activate_this.py'
[Sat Dec 04 21:22:35.343637 2021] [wsgi:error] [pid 5933:tid 140385016239872] [remote 192.168.1.237:49046] mod_wsgi (pid=5933): Target WSGI script '/var/www/mainapp/mainapp/mainapp.wsgi' cannot be loaded as Python module.
[Sat Dec 04 21:22:35.343820 2021] [wsgi:error] [pid 5933:tid 140385016239872] [remote 192.168.1.237:49046] mod_wsgi (pid=5933): Exception occurred processing WSGI script '/var/www/mainapp/mainapp/mainapp.wsgi'.
[Sat Dec 04 21:22:35.350920 2021] [wsgi:error] [pid 5933:tid 140385016239872] [remote 192.168.1.237:49046] Traceback (most recent call last):
[Sat Dec 04 21:22:35.350952 2021] [wsgi:error] [pid 5933:tid 140385016239872] [remote 192.168.1.237:49046]   File "/var/www/mainapp/mainapp/mainapp.wsgi", line 6, in <module>
[Sat Dec 04 21:22:35.350956 2021] [wsgi:error] [pid 5933:tid 140385016239872] [remote 192.168.1.237:49046]     with open(activate_this) as file_:
[Sat Dec 04 21:22:35.350992 2021] [wsgi:error] [pid 5933:tid 140385016239872] [remote 192.168.1.237:49046] PermissionError: [Errno 13] Permission denied: '/home/server/.local/share/virtualenvs/mainapp-c6pGQO_3/bin/activate_this.py'
[Sat Dec 04 21:28:32.539367 2021] [wsgi:error] [pid 6037:tid 140385016239872] [remote 192.168.1.237:49060] mod_wsgi (pid=6037): Target WSGI script '/var/www/mainapp/mainapp/mainapp.wsgi' cannot be loaded as Python module.
[Sat Dec 04 21:28:32.539415 2021] [wsgi:error] [pid 6037:tid 140385016239872] [remote 192.168.1.237:49060] mod_wsgi (pid=6037): Exception occurred processing WSGI script '/var/www/mainapp/mainapp/mainapp.wsgi'.
[Sat Dec 04 21:28:32.542677 2021] [wsgi:error] [pid 6037:tid 140385016239872] [remote 192.168.1.237:49060] Traceback (most recent call last):
[Sat Dec 04 21:28:32.542699 2021] [wsgi:error] [pid 6037:tid 140385016239872] [remote 192.168.1.237:49060]   File "/var/www/mainapp/mainapp/mainapp.wsgi", line 6, in <module>
[Sat Dec 04 21:28:32.542704 2021] [wsgi:error] [pid 6037:tid 140385016239872] [remote 192.168.1.237:49060]     with open(activate_this) as file_:
[Sat Dec 04 21:28:32.542716 2021] [wsgi:error] [pid 6037:tid 140385016239872] [remote 192.168.1.237:49060] PermissionError: [Errno 13] Permission denied: '/home/server/.local/share/virtualenvs/mainapp-c6pGQO_3/bin/activate_this.py'
[Sat Dec 04 21:28:37.168414 2021] [wsgi:error] [pid 6037:tid 140384982652672] [remote 192.168.1.237:49064] mod_wsgi (pid=6037): Target WSGI script '/var/www/mainapp/mainapp/mainapp.wsgi' cannot be loaded as Python module.
[Sat Dec 04 21:28:37.168460 2021] [wsgi:error] [pid 6037:tid 140384982652672] [remote 192.168.1.237:49064] mod_wsgi (pid=6037): Exception occurred processing WSGI script '/var/www/mainapp/mainapp/mainapp.wsgi'.
[Sat Dec 04 21:28:37.168520 2021] [wsgi:error] [pid 6037:tid 140384982652672] [remote 192.168.1.237:49064] Traceback (most recent call last):
[Sat Dec 04 21:28:37.168540 2021] [wsgi:error] [pid 6037:tid 140384982652672] [remote 192.168.1.237:49064]   File "/var/www/mainapp/mainapp/mainapp.wsgi", line 6, in <module>
[Sat Dec 04 21:28:37.168544 2021] [wsgi:error] [pid 6037:tid 140384982652672] [remote 192.168.1.237:49064]     with open(activate_this) as file_:
[Sat Dec 04 21:28:37.168555 2021] [wsgi:error] [pid 6037:tid 140384982652672] [remote 192.168.1.237:49064] PermissionError: [Errno 13] Permission denied: '/home/server/.local/share/virtualenvs/mainapp-c6pGQO_3/bin/activate_this.py'
[Sat Dec 04 21:37:40.015959 2021] [wsgi:error] [pid 6037:tid 140385016239872] [remote 192.168.1.237:49164] mod_wsgi (pid=6037): Target WSGI script '/var/www/mainapp/mainapp/mainapp.wsgi' cannot be loaded as Python module.
[Sat Dec 04 21:37:40.016011 2021] [wsgi:error] [pid 6037:tid 140385016239872] [remote 192.168.1.237:49164] mod_wsgi (pid=6037): Exception occurred processing WSGI script '/var/www/mainapp/mainapp/mainapp.wsgi'.
[Sat Dec 04 21:37:40.016074 2021] [wsgi:error] [pid 6037:tid 140385016239872] [remote 192.168.1.237:49164] Traceback (most recent call last):
[Sat Dec 04 21:37:40.016090 2021] [wsgi:error] [pid 6037:tid 140385016239872] [remote 192.168.1.237:49164]   File "/var/www/mainapp/mainapp/mainapp.wsgi", line 6, in <module>
[Sat Dec 04 21:37:40.016094 2021] [wsgi:error] [pid 6037:tid 140385016239872] [remote 192.168.1.237:49164]     with open(activate_this) as file_:
[Sat Dec 04 21:37:40.016104 2021] [wsgi:error] [pid 6037:tid 140385016239872] [remote 192.168.1.237:49164] PermissionError: [Errno 13] Permission denied: '/home/server/.local/share/virtualenvs/mainapp-c6pGQO_3/bin/activate_this.py'
[Sat Dec 04 21:53:50.151985 2021] [wsgi:error] [pid 6604:tid 140385016239872] [remote 192.168.1.237:49328] mod_wsgi (pid=6604): Target WSGI script '/var/www/mainapp/mainapp/mainapp.wsgi' cannot be loaded as Python module.
[Sat Dec 04 21:53:50.152026 2021] [wsgi:error] [pid 6604:tid 140385016239872] [remote 192.168.1.237:49328] mod_wsgi (pid=6604): Exception occurred processing WSGI script '/var/www/mainapp/mainapp/mainapp.wsgi'.
[Sat Dec 04 21:53:50.155282 2021] [wsgi:error] [pid 6604:tid 140385016239872] [remote 192.168.1.237:49328] Traceback (most recent call last):
[Sat Dec 04 21:53:50.155302 2021] [wsgi:error] [pid 6604:tid 140385016239872] [remote 192.168.1.237:49328]   File "/var/www/mainapp/mainapp/mainapp.wsgi", line 8, in <module>
[Sat Dec 04 21:53:50.155307 2021] [wsgi:error] [pid 6604:tid 140385016239872] [remote 192.168.1.237:49328]     with open(activate_this) as file_:
[Sat Dec 04 21:53:50.155318 2021] [wsgi:error] [pid 6604:tid 140385016239872] [remote 192.168.1.237:49328] PermissionError: [Errno 13] Permission denied: '/home/server/.local/share/virtualenvs/mainapp-c6pGQO_3/bin/activate_this.py'
[Sat Dec 04 21:53:50.951256 2021] [wsgi:error] [pid 6604:tid 140384982652672] [remote 192.168.1.237:49330] mod_wsgi (pid=6604): Target WSGI script '/var/www/mainapp/mainapp/mainapp.wsgi' cannot be loaded as Python module.
[Sat Dec 04 21:53:50.951291 2021] [wsgi:error] [pid 6604:tid 140384982652672] [remote 192.168.1.237:49330] mod_wsgi (pid=6604): Exception occurred processing WSGI script '/var/www/mainapp/mainapp/mainapp.wsgi'.
[Sat Dec 04 21:53:50.951347 2021] [wsgi:error] [pid 6604:tid 140384982652672] [remote 192.168.1.237:49330] Traceback (most recent call last):
[Sat Dec 04 21:53:50.951364 2021] [wsgi:error] [pid 6604:tid 140384982652672] [remote 192.168.1.237:49330]   File "/var/www/mainapp/mainapp/mainapp.wsgi", line 8, in <module>
[Sat Dec 04 21:53:50.951367 2021] [wsgi:error] [pid 6604:tid 140384982652672] [remote 192.168.1.237:49330]     with open(activate_this) as file_:
[Sat Dec 04 21:53:50.951378 2021] [wsgi:error] [pid 6604:tid 140384982652672] [remote 192.168.1.237:49330] PermissionError: [Errno 13] Permission denied: '/home/server/.local/share/virtualenvs/mainapp-c6pGQO_3/bin/activate_this.py'
[Sat Dec 04 23:06:51.222031 2021] [wsgi:error] [pid 7147:tid 140385016239872] [remote 192.168.1.237:49436] mod_wsgi (pid=7147): Target WSGI script '/var/www/mainapp/mainapp/mainapp.wsgi' cannot be loaded as Python module.
[Sat Dec 04 23:06:51.222161 2021] [wsgi:error] [pid 7147:tid 140385016239872] [remote 192.168.1.237:49436] mod_wsgi (pid=7147): Exception occurred processing WSGI script '/var/www/mainapp/mainapp/mainapp.wsgi'.
[Sat Dec 04 23:06:51.231225 2021] [wsgi:error] [pid 7147:tid 140385016239872] [remote 192.168.1.237:49436] Traceback (most recent call last):
[Sat Dec 04 23:06:51.231296 2021] [wsgi:error] [pid 7147:tid 140385016239872] [remote 192.168.1.237:49436]   File "/var/www/mainapp/mainapp/mainapp.wsgi", line 8, in <module>
[Sat Dec 04 23:06:51.231307 2021] [wsgi:error] [pid 7147:tid 140385016239872] [remote 192.168.1.237:49436]     with open(activate_this) as file_:
[Sat Dec 04 23:06:51.231339 2021] [wsgi:error] [pid 7147:tid 140385016239872] [remote 192.168.1.237:49436] PermissionError: [Errno 13] Permission denied: '/home/server/.local/share/virtualenvs/mainapp-c6pGQO_3/bin/activate_this.py'
[Sat Dec 04 23:06:52.639481 2021] [wsgi:error] [pid 7147:tid 140384982652672] [remote 192.168.1.237:49440] mod_wsgi (pid=7147): Target WSGI script '/var/www/mainapp/mainapp/mainapp.wsgi' cannot be loaded as Python module.
[Sat Dec 04 23:06:52.639633 2021] [wsgi:error] [pid 7147:tid 140384982652672] [remote 192.168.1.237:49440] mod_wsgi (pid=7147): Exception occurred processing WSGI script '/var/www/mainapp/mainapp/mainapp.wsgi'.
[Sat Dec 04 23:06:52.639835 2021] [wsgi:error] [pid 7147:tid 140384982652672] [remote 192.168.1.237:49440] Traceback (most recent call last):
[Sat Dec 04 23:06:52.639914 2021] [wsgi:error] [pid 7147:tid 140384982652672] [remote 192.168.1.237:49440]   File "/var/www/mainapp/mainapp/mainapp.wsgi", line 8, in <module>
[Sat Dec 04 23:06:52.639931 2021] [wsgi:error] [pid 7147:tid 140384982652672] [remote 192.168.1.237:49440]     with open(activate_this) as file_:
[Sat Dec 04 23:06:52.639976 2021] [wsgi:error] [pid 7147:tid 140384982652672] [remote 192.168.1.237:49440] PermissionError: [Errno 13] Permission denied: '/home/server/.local/share/virtualenvs/mainapp-c6pGQO_3/bin/activate_this.py'
[Sat Dec 04 23:39:58.756878 2021] [wsgi:error] [pid 7833:tid 140385024632576] [client 192.168.1.237:49578] mod_wsgi (pid=7833): Target WSGI script '/var/www/mainapp/mainapp/mainapp.wsgi' cannot be loaded as Python module.
[Sat Dec 04 23:39:58.756984 2021] [wsgi:error] [pid 7833:tid 140385024632576] [client 192.168.1.237:49578] mod_wsgi (pid=7833): Exception occurred processing WSGI script '/var/www/mainapp/mainapp/mainapp.wsgi'.
[Sat Dec 04 23:39:58.757312 2021] [wsgi:error] [pid 7833:tid 140385024632576] [client 192.168.1.237:49578] Traceback (most recent call last):
[Sat Dec 04 23:39:58.757373 2021] [wsgi:error] [pid 7833:tid 140385024632576] [client 192.168.1.237:49578]   File "/var/www/mainapp/mainapp/mainapp.wsgi", line 8, in <module>
[Sat Dec 04 23:39:58.757380 2021] [wsgi:error] [pid 7833:tid 140385024632576] [client 192.168.1.237:49578]     with open(activate_this) as file_:
[Sat Dec 04 23:39:58.757414 2021] [wsgi:error] [pid 7833:tid 140385024632576] [client 192.168.1.237:49578] PermissionError: [Errno 13] Permission denied: '/home/server/.local/share/virtualenvs/mainapp-c6pGQO_3/bin/activate_this.py'
[Sat Dec 04 23:40:00.083811 2021] [wsgi:error] [pid 7833:tid 140385016239872] [client 192.168.1.237:49580] mod_wsgi (pid=7833): Target WSGI script '/var/www/mainapp/mainapp/mainapp.wsgi' cannot be loaded as Python module.
[Sat Dec 04 23:40:00.083950 2021] [wsgi:error] [pid 7833:tid 140385016239872] [client 192.168.1.237:49580] mod_wsgi (pid=7833): Exception occurred processing WSGI script '/var/www/mainapp/mainapp/mainapp.wsgi'.
[Sat Dec 04 23:40:00.084169 2021] [wsgi:error] [pid 7833:tid 140385016239872] [client 192.168.1.237:49580] Traceback (most recent call last):
[Sat Dec 04 23:40:00.084289 2021] [wsgi:error] [pid 7833:tid 140385016239872] [client 192.168.1.237:49580]   File "/var/www/mainapp/mainapp/mainapp.wsgi", line 8, in <module>
[Sat Dec 04 23:40:00.084308 2021] [wsgi:error] [pid 7833:tid 140385016239872] [client 192.168.1.237:49580]     with open(activate_this) as file_:
[Sat Dec 04 23:40:00.084356 2021] [wsgi:error] [pid 7833:tid 140385016239872] [client 192.168.1.237:49580] PermissionError: [Errno 13] Permission denied: '/home/server/.local/share/virtualenvs/mainapp-c6pGQO_3/bin/activate_this.py'
[Sun Dec 05 00:01:45.756453 2021] [wsgi:error] [pid 8268:tid 140385016239872] [remote 192.168.1.237:49632] mod_wsgi (pid=8268): Target WSGI script '/var/www/mainapp/mainapp/mainapp.wsgi' cannot be loaded as Python module.
[Sun Dec 05 00:01:45.756498 2021] [wsgi:error] [pid 8268:tid 140385016239872] [remote 192.168.1.237:49632] mod_wsgi (pid=8268): Exception occurred processing WSGI script '/var/www/mainapp/mainapp/mainapp.wsgi'.
[Sun Dec 05 00:01:45.756675 2021] [wsgi:error] [pid 8268:tid 140385016239872] [remote 192.168.1.237:49632] Traceback (most recent call last):
[Sun Dec 05 00:01:45.756715 2021] [wsgi:error] [pid 8268:tid 140385016239872] [remote 192.168.1.237:49632]   File "/var/www/mainapp/mainapp/mainapp.wsgi", line 8, in <module>
[Sun Dec 05 00:01:45.756720 2021] [wsgi:error] [pid 8268:tid 140385016239872] [remote 192.168.1.237:49632]     with open(activate_this) as file_:
[Sun Dec 05 00:01:45.756733 2021] [wsgi:error] [pid 8268:tid 140385016239872] [remote 192.168.1.237:49632] PermissionError: [Errno 13] Permission denied: '/home/server/.local/share/virtualenvs/mainapp-c6pGQO_3/bin/activate_this.py'
[Sun Dec 05 00:01:46.998054 2021] [wsgi:error] [pid 8268:tid 140384982652672] [remote 192.168.1.237:49634] mod_wsgi (pid=8268): Target WSGI script '/var/www/mainapp/mainapp/mainapp.wsgi' cannot be loaded as Python module.
[Sun Dec 05 00:01:46.998222 2021] [wsgi:error] [pid 8268:tid 140384982652672] [remote 192.168.1.237:49634] mod_wsgi (pid=8268): Exception occurred processing WSGI script '/var/www/mainapp/mainapp/mainapp.wsgi'.
[Sun Dec 05 00:01:46.998485 2021] [wsgi:error] [pid 8268:tid 140384982652672] [remote 192.168.1.237:49634] Traceback (most recent call last):
[Sun Dec 05 00:01:46.998573 2021] [wsgi:error] [pid 8268:tid 140384982652672] [remote 192.168.1.237:49634]   File "/var/www/mainapp/mainapp/mainapp.wsgi", line 8, in <module>
[Sun Dec 05 00:01:46.998592 2021] [wsgi:error] [pid 8268:tid 140384982652672] [remote 192.168.1.237:49634]     with open(activate_this) as file_:
[Sun Dec 05 00:01:46.998640 2021] [wsgi:error] [pid 8268:tid 140384982652672] [remote 192.168.1.237:49634] PermissionError: [Errno 13] Permission denied: '/home/server/.local/share/virtualenvs/mainapp-c6pGQO_3/bin/activate_this.py'
[Sun Dec 05 00:09:32.389212 2021] [wsgi:error] [pid 8664:tid 140385016239872] [remote 192.168.1.237:49676] mod_wsgi (pid=8664): Target WSGI script '/var/www/mainapp/mainapp/mainapp.wsgi' cannot be loaded as Python module.
[Sun Dec 05 00:09:32.389283 2021] [wsgi:error] [pid 8664:tid 140385016239872] [remote 192.168.1.237:49676] mod_wsgi (pid=8664): Exception occurred processing WSGI script '/var/www/mainapp/mainapp/mainapp.wsgi'.
[Sun Dec 05 00:09:32.389655 2021] [wsgi:error] [pid 8664:tid 140385016239872] [remote 192.168.1.237:49676] Traceback (most recent call last):
[Sun Dec 05 00:09:32.389677 2021] [wsgi:error] [pid 8664:tid 140385016239872] [remote 192.168.1.237:49676]   File "/var/www/mainapp/mainapp/mainapp.wsgi", line 8, in <module>
[Sun Dec 05 00:09:32.389699 2021] [wsgi:error] [pid 8664:tid 140385016239872] [remote 192.168.1.237:49676]     with open(activate_this) as file_:
[Sun Dec 05 00:09:32.389715 2021] [wsgi:error] [pid 8664:tid 140385016239872] [remote 192.168.1.237:49676] PermissionError: [Errno 13] Permission denied: '/home/server/.local/share/virtualenvs/mainapp-c6pGQO_3/bin/activate_this.py'
[Sun Dec 05 00:09:36.933511 2021] [wsgi:error] [pid 8664:tid 140384982652672] [remote 192.168.1.237:49678] mod_wsgi (pid=8664): Target WSGI script '/var/www/mainapp/mainapp/mainapp.wsgi' cannot be loaded as Python module.
[Sun Dec 05 00:09:36.933660 2021] [wsgi:error] [pid 8664:tid 140384982652672] [remote 192.168.1.237:49678] mod_wsgi (pid=8664): Exception occurred processing WSGI script '/var/www/mainapp/mainapp/mainapp.wsgi'.
[Sun Dec 05 00:09:36.933872 2021] [wsgi:error] [pid 8664:tid 140384982652672] [remote 192.168.1.237:49678] Traceback (most recent call last):
[Sun Dec 05 00:09:36.933953 2021] [wsgi:error] [pid 8664:tid 140384982652672] [remote 192.168.1.237:49678]   File "/var/www/mainapp/mainapp/mainapp.wsgi", line 8, in <module>
[Sun Dec 05 00:09:36.933973 2021] [wsgi:error] [pid 8664:tid 140384982652672] [remote 192.168.1.237:49678]     with open(activate_this) as file_:
[Sun Dec 05 00:09:36.934019 2021] [wsgi:error] [pid 8664:tid 140384982652672] [remote 192.168.1.237:49678] PermissionError: [Errno 13] Permission denied: '/home/server/.local/share/virtualenvs/mainapp-c6pGQO_3/bin/activate_this.py'
[Sun Dec 05 00:09:36.974733 2021] [wsgi:error] [pid 8664:tid 140385016239872] [remote 192.168.1.237:49680] mod_wsgi (pid=8664): Target WSGI script '/var/www/mainapp/mainapp/mainapp.wsgi' cannot be loaded as Python module.
[Sun Dec 05 00:09:36.974803 2021] [wsgi:error] [pid 8664:tid 140385016239872] [remote 192.168.1.237:49680] mod_wsgi (pid=8664): Exception occurred processing WSGI script '/var/www/mainapp/mainapp/mainapp.wsgi'.
[Sun Dec 05 00:09:36.974877 2021] [wsgi:error] [pid 8664:tid 140385016239872] [remote 192.168.1.237:49680] Traceback (most recent call last):
[Sun Dec 05 00:09:36.974899 2021] [wsgi:error] [pid 8664:tid 140385016239872] [remote 192.168.1.237:49680]   File "/var/www/mainapp/mainapp/mainapp.wsgi", line 8, in <module>
[Sun Dec 05 00:09:36.974905 2021] [wsgi:error] [pid 8664:tid 140385016239872] [remote 192.168.1.237:49680]     with open(activate_this) as file_:
[Sun Dec 05 00:09:36.974919 2021] [wsgi:error] [pid 8664:tid 140385016239872] [remote 192.168.1.237:49680] PermissionError: [Errno 13] Permission denied: '/home/server/.local/share/virtualenvs/mainapp-c6pGQO_3/bin/activate_this.py'
[Sun Dec 05 00:14:43.845202 2021] [wsgi:error] [pid 8888:tid 140385016239872] [remote 192.168.1.237:49768] mod_wsgi (pid=8888): Target WSGI script '/var/www/mainapp/mainapp/mainapp.wsgi' cannot be loaded as Python module.
[Sun Dec 05 00:14:43.845240 2021] [wsgi:error] [pid 8888:tid 140385016239872] [remote 192.168.1.237:49768] mod_wsgi (pid=8888): Exception occurred processing WSGI script '/var/www/mainapp/mainapp/mainapp.wsgi'.
[Sun Dec 05 00:14:43.845366 2021] [wsgi:error] [pid 8888:tid 140385016239872] [remote 192.168.1.237:49768] Traceback (most recent call last):
[Sun Dec 05 00:14:43.845385 2021] [wsgi:error] [pid 8888:tid 140385016239872] [remote 192.168.1.237:49768]   File "/var/www/mainapp/mainapp/mainapp.wsgi", line 8, in <module>
[Sun Dec 05 00:14:43.845390 2021] [wsgi:error] [pid 8888:tid 140385016239872] [remote 192.168.1.237:49768]     with open(activate_this, encoding='utf-8') as file_:
[Sun Dec 05 00:14:43.845402 2021] [wsgi:error] [pid 8888:tid 140385016239872] [remote 192.168.1.237:49768] PermissionError: [Errno 13] Permission denied: '/home/server/.local/share/virtualenvs/mainapp-c6pGQO_3/bin/activate_this.py'
[Sun Dec 05 00:14:46.233032 2021] [wsgi:error] [pid 8888:tid 140384982652672] [remote 192.168.1.237:49770] mod_wsgi (pid=8888): Target WSGI script '/var/www/mainapp/mainapp/mainapp.wsgi' cannot be loaded as Python module.
[Sun Dec 05 00:14:46.233186 2021] [wsgi:error] [pid 8888:tid 140384982652672] [remote 192.168.1.237:49770] mod_wsgi (pid=8888): Exception occurred processing WSGI script '/var/www/mainapp/mainapp/mainapp.wsgi'.
[Sun Dec 05 00:14:46.233387 2021] [wsgi:error] [pid 8888:tid 140384982652672] [remote 192.168.1.237:49770] Traceback (most recent call last):
[Sun Dec 05 00:14:46.233466 2021] [wsgi:error] [pid 8888:tid 140384982652672] [remote 192.168.1.237:49770]   File "/var/www/mainapp/mainapp/mainapp.wsgi", line 8, in <module>
[Sun Dec 05 00:14:46.233485 2021] [wsgi:error] [pid 8888:tid 140384982652672] [remote 192.168.1.237:49770]     with open(activate_this, encoding='utf-8') as file_:
[Sun Dec 05 00:14:46.233530 2021] [wsgi:error] [pid 8888:tid 140384982652672] [remote 192.168.1.237:49770] PermissionError: [Errno 13] Permission denied: '/home/server/.local/share/virtualenvs/mainapp-c6pGQO_3/bin/activate_this.py'
[Sun Dec 05 00:14:49.496290 2021] [wsgi:error] [pid 8888:tid 140385016239872] [remote 192.168.1.237:49772] mod_wsgi (pid=8888): Target WSGI script '/var/www/mainapp/mainapp/mainapp.wsgi' cannot be loaded as Python module.
[Sun Dec 05 00:14:49.496387 2021] [wsgi:error] [pid 8888:tid 140385016239872] [remote 192.168.1.237:49772] mod_wsgi (pid=8888): Exception occurred processing WSGI script '/var/www/mainapp/mainapp/mainapp.wsgi'.
[Sun Dec 05 00:14:49.496536 2021] [wsgi:error] [pid 8888:tid 140385016239872] [remote 192.168.1.237:49772] Traceback (most recent call last):
[Sun Dec 05 00:14:49.496587 2021] [wsgi:error] [pid 8888:tid 140385016239872] [remote 192.168.1.237:49772]   File "/var/www/mainapp/mainapp/mainapp.wsgi", line 8, in <module>
[Sun Dec 05 00:14:49.496600 2021] [wsgi:error] [pid 8888:tid 140385016239872] [remote 192.168.1.237:49772]     with open(activate_this, encoding='utf-8') as file_:
[Sun Dec 05 00:14:49.496650 2021] [wsgi:error] [pid 8888:tid 140385016239872] [remote 192.168.1.237:49772] PermissionError: [Errno 13] Permission denied: '/home/server/.local/share/virtualenvs/mainapp-c6pGQO_3/bin/activate_this.py'
[Sun Dec 05 00:35:27.916715 2021] [wsgi:error] [pid 10316:tid 140385016239872] [remote 192.168.1.237:49828] mod_wsgi (pid=10316): Target WSGI script '/var/www/mainapp/mainapp/mainapp.wsgi' cannot be loaded as Python module.
[Sun Dec 05 00:35:27.916893 2021] [wsgi:error] [pid 10316:tid 140385016239872] [remote 192.168.1.237:49828] mod_wsgi (pid=10316): Exception occurred processing WSGI script '/var/www/mainapp/mainapp/mainapp.wsgi'.
[Sun Dec 05 00:35:27.927858 2021] [wsgi:error] [pid 10316:tid 140385016239872] [remote 192.168.1.237:49828] Traceback (most recent call last):
[Sun Dec 05 00:35:27.927939 2021] [wsgi:error] [pid 10316:tid 140385016239872] [remote 192.168.1.237:49828]   File "/var/www/mainapp/mainapp/mainapp.wsgi", line 8, in <module>
[Sun Dec 05 00:35:27.927955 2021] [wsgi:error] [pid 10316:tid 140385016239872] [remote 192.168.1.237:49828]     with open(activate_this, encoding='utf-8') as file_:
[Sun Dec 05 00:35:27.927989 2021] [wsgi:error] [pid 10316:tid 140385016239872] [remote 192.168.1.237:49828] PermissionError: [Errno 13] Permission denied: '/home/server/.local/share/virtualenvs/mainapp-c6pGQO_3/bin/activate_this.py'
[Sun Dec 05 00:35:29.380800 2021] [wsgi:error] [pid 10316:tid 140384982652672] [remote 192.168.1.237:49830] mod_wsgi (pid=10316): Target WSGI script '/var/www/mainapp/mainapp/mainapp.wsgi' cannot be loaded as Python module.
[Sun Dec 05 00:35:29.380953 2021] [wsgi:error] [pid 10316:tid 140384982652672] [remote 192.168.1.237:49830] mod_wsgi (pid=10316): Exception occurred processing WSGI script '/var/www/mainapp/mainapp/mainapp.wsgi'.
[Sun Dec 05 00:35:29.381153 2021] [wsgi:error] [pid 10316:tid 140384982652672] [remote 192.168.1.237:49830] Traceback (most recent call last):
[Sun Dec 05 00:35:29.381244 2021] [wsgi:error] [pid 10316:tid 140384982652672] [remote 192.168.1.237:49830]   File "/var/www/mainapp/mainapp/mainapp.wsgi", line 8, in <module>
[Sun Dec 05 00:35:29.381264 2021] [wsgi:error] [pid 10316:tid 140384982652672] [remote 192.168.1.237:49830]     with open(activate_this, encoding='utf-8') as file_:
[Sun Dec 05 00:35:29.381322 2021] [wsgi:error] [pid 10316:tid 140384982652672] [remote 192.168.1.237:49830] PermissionError: [Errno 13] Permission denied: '/home/server/.local/share/virtualenvs/mainapp-c6pGQO_3/bin/activate_this.py'
[Sun Dec 05 00:35:35.916351 2021] [wsgi:error] [pid 10316:tid 140385016239872] [remote 127.0.0.1:56966] mod_wsgi (pid=10316): Target WSGI script '/var/www/mainapp/mainapp/mainapp.wsgi' cannot be loaded as Python module.
[Sun Dec 05 00:35:35.916490 2021] [wsgi:error] [pid 10316:tid 140385016239872] [remote 127.0.0.1:56966] mod_wsgi (pid=10316): Exception occurred processing WSGI script '/var/www/mainapp/mainapp/mainapp.wsgi'.
[Sun Dec 05 00:35:35.916692 2021] [wsgi:error] [pid 10316:tid 140385016239872] [remote 127.0.0.1:56966] Traceback (most recent call last):
[Sun Dec 05 00:35:35.916764 2021] [wsgi:error] [pid 10316:tid 140385016239872] [remote 127.0.0.1:56966]   File "/var/www/mainapp/mainapp/mainapp.wsgi", line 8, in <module>
[Sun Dec 05 00:35:35.916785 2021] [wsgi:error] [pid 10316:tid 140385016239872] [remote 127.0.0.1:56966]     with open(activate_this, encoding='utf-8') as file_:
[Sun Dec 05 00:35:35.916831 2021] [wsgi:error] [pid 10316:tid 140385016239872] [remote 127.0.0.1:56966] PermissionError: [Errno 13] Permission denied: '/home/server/.local/share/virtualenvs/mainapp-c6pGQO_3/bin/activate_this.py'
[Sun Dec 05 00:35:35.981692 2021] [wsgi:error] [pid 10316:tid 140384982652672] [remote 127.0.0.1:56968] mod_wsgi (pid=10316): Target WSGI script '/var/www/mainapp/mainapp/mainapp.wsgi' cannot be loaded as Python module.
[Sun Dec 05 00:35:35.981728 2021] [wsgi:error] [pid 10316:tid 140384982652672] [remote 127.0.0.1:56968] mod_wsgi (pid=10316): Exception occurred processing WSGI script '/var/www/mainapp/mainapp/mainapp.wsgi'.
[Sun Dec 05 00:35:35.981799 2021] [wsgi:error] [pid 10316:tid 140384982652672] [remote 127.0.0.1:56968] Traceback (most recent call last):
[Sun Dec 05 00:35:35.981818 2021] [wsgi:error] [pid 10316:tid 140384982652672] [remote 127.0.0.1:56968]   File "/var/www/mainapp/mainapp/mainapp.wsgi", line 8, in <module>
[Sun Dec 05 00:35:35.981822 2021] [wsgi:error] [pid 10316:tid 140384982652672] [remote 127.0.0.1:56968]     with open(activate_this, encoding='utf-8') as file_:
[Sun Dec 05 00:35:35.981834 2021] [wsgi:error] [pid 10316:tid 140384982652672] [remote 127.0.0.1:56968] PermissionError: [Errno 13] Permission denied: '/home/server/.local/share/virtualenvs/mainapp-c6pGQO_3/bin/activate_this.py'
[Sun Dec 05 00:35:55.046167 2021] [wsgi:error] [pid 10316:tid 140385016239872] [remote 192.168.1.237:49838] mod_wsgi (pid=10316): Target WSGI script '/var/www/mainapp/mainapp/mainapp.wsgi' cannot be loaded as Python module.
[Sun Dec 05 00:35:55.046245 2021] [wsgi:error] [pid 10316:tid 140385016239872] [remote 192.168.1.237:49838] mod_wsgi (pid=10316): Exception occurred processing WSGI script '/var/www/mainapp/mainapp/mainapp.wsgi'.
[Sun Dec 05 00:35:55.046707 2021] [wsgi:error] [pid 10316:tid 140385016239872] [remote 192.168.1.237:49838] Traceback (most recent call last):
[Sun Dec 05 00:35:55.046728 2021] [wsgi:error] [pid 10316:tid 140385016239872] [remote 192.168.1.237:49838]   File "/var/www/mainapp/mainapp/mainapp.wsgi", line 8, in <module>
[Sun Dec 05 00:35:55.046751 2021] [wsgi:error] [pid 10316:tid 140385016239872] [remote 192.168.1.237:49838]     with open(activate_this, encoding='utf-8') as file_:
[Sun Dec 05 00:35:55.046763 2021] [wsgi:error] [pid 10316:tid 140385016239872] [remote 192.168.1.237:49838] PermissionError: [Errno 13] Permission denied: '/home/server/.local/share/virtualenvs/mainapp-c6pGQO_3/bin/activate_this.py'
[Sun Dec 05 00:39:50.090208 2021] [wsgi:error] [pid 10643:tid 140385016239872] [remote 192.168.1.237:49888] mod_wsgi (pid=10643): Target WSGI script '/var/www/mainapp/mainapp/mainapp.wsgi' cannot be loaded as Python module.
[Sun Dec 05 00:39:50.090393 2021] [wsgi:error] [pid 10643:tid 140385016239872] [remote 192.168.1.237:49888] mod_wsgi (pid=10643): Exception occurred processing WSGI script '/var/www/mainapp/mainapp/mainapp.wsgi'.
[Sun Dec 05 00:39:50.106817 2021] [wsgi:error] [pid 10643:tid 140385016239872] [remote 192.168.1.237:49888] Traceback (most recent call last):
[Sun Dec 05 00:39:50.106929 2021] [wsgi:error] [pid 10643:tid 140385016239872] [remote 192.168.1.237:49888]   File "/var/www/mainapp/mainapp/mainapp.wsgi", line 8, in <module>
[Sun Dec 05 00:39:50.106953 2021] [wsgi:error] [pid 10643:tid 140385016239872] [remote 192.168.1.237:49888]     with open(activate_this, "r") as file_:
[Sun Dec 05 00:39:50.107002 2021] [wsgi:error] [pid 10643:tid 140385016239872] [remote 192.168.1.237:49888] PermissionError: [Errno 13] Permission denied: '/home/server/.local/share/virtualenvs/mainapp-c6pGQO_3/bin/activate_this.py'
[Sun Dec 05 00:39:52.686657 2021] [wsgi:error] [pid 10643:tid 140384999454464] [remote 192.168.1.237:49890] mod_wsgi (pid=10643): Target WSGI script '/var/www/mainapp/mainapp/mainapp.wsgi' cannot be loaded as Python module.
[Sun Dec 05 00:39:52.686700 2021] [wsgi:error] [pid 10643:tid 140384999454464] [remote 192.168.1.237:49890] mod_wsgi (pid=10643): Exception occurred processing WSGI script '/var/www/mainapp/mainapp/mainapp.wsgi'.
[Sun Dec 05 00:39:52.686759 2021] [wsgi:error] [pid 10643:tid 140384999454464] [remote 192.168.1.237:49890] Traceback (most recent call last):
[Sun Dec 05 00:39:52.686778 2021] [wsgi:error] [pid 10643:tid 140384999454464] [remote 192.168.1.237:49890]   File "/var/www/mainapp/mainapp/mainapp.wsgi", line 8, in <module>
[Sun Dec 05 00:39:52.686782 2021] [wsgi:error] [pid 10643:tid 140384999454464] [remote 192.168.1.237:49890]     with open(activate_this, "r") as file_:
[Sun Dec 05 00:39:52.686793 2021] [wsgi:error] [pid 10643:tid 140384999454464] [remote 192.168.1.237:49890] PermissionError: [Errno 13] Permission denied: '/home/server/.local/share/virtualenvs/mainapp-c6pGQO_3/bin/activate_this.py'
[Sun Dec 05 00:46:34.817416 2021] [wsgi:error] [pid 10847:tid 140385016239872] [remote 192.168.1.237:49958] mod_wsgi (pid=10847): Target WSGI script '/var/www/mainapp/mainapp/mainapp.wsgi' cannot be loaded as Python module.
[Sun Dec 05 00:46:34.817547 2021] [wsgi:error] [pid 10847:tid 140385016239872] [remote 192.168.1.237:49958] mod_wsgi (pid=10847): Exception occurred processing WSGI script '/var/www/mainapp/mainapp/mainapp.wsgi'.
[Sun Dec 05 00:46:34.829442 2021] [wsgi:error] [pid 10847:tid 140385016239872] [remote 192.168.1.237:49958] Traceback (most recent call last):
[Sun Dec 05 00:46:34.829549 2021] [wsgi:error] [pid 10847:tid 140385016239872] [remote 192.168.1.237:49958]   File "/var/www/mainapp/mainapp/mainapp.wsgi", line 8, in <module>
[Sun Dec 05 00:46:34.829566 2021] [wsgi:error] [pid 10847:tid 140385016239872] [remote 192.168.1.237:49958]     with open(activate_this, "r") as file_:
[Sun Dec 05 00:46:34.829606 2021] [wsgi:error] [pid 10847:tid 140385016239872] [remote 192.168.1.237:49958] PermissionError: [Errno 13] Permission denied: '/home/server/.local/share/virtualenvs/mainapp-c6pGQO_3/bin/activate_this.py'
[Sun Dec 05 00:46:36.681867 2021] [wsgi:error] [pid 10847:tid 140384982652672] [remote 192.168.1.237:49960] mod_wsgi (pid=10847): Target WSGI script '/var/www/mainapp/mainapp/mainapp.wsgi' cannot be loaded as Python module.
[Sun Dec 05 00:46:36.682053 2021] [wsgi:error] [pid 10847:tid 140384982652672] [remote 192.168.1.237:49960] mod_wsgi (pid=10847): Exception occurred processing WSGI script '/var/www/mainapp/mainapp/mainapp.wsgi'.
[Sun Dec 05 00:46:36.682282 2021] [wsgi:error] [pid 10847:tid 140384982652672] [remote 192.168.1.237:49960] Traceback (most recent call last):
[Sun Dec 05 00:46:36.682372 2021] [wsgi:error] [pid 10847:tid 140384982652672] [remote 192.168.1.237:49960]   File "/var/www/mainapp/mainapp/mainapp.wsgi", line 8, in <module>
[Sun Dec 05 00:46:36.682391 2021] [wsgi:error] [pid 10847:tid 140384982652672] [remote 192.168.1.237:49960]     with open(activate_this, "r") as file_:
[Sun Dec 05 00:46:36.682441 2021] [wsgi:error] [pid 10847:tid 140384982652672] [remote 192.168.1.237:49960] PermissionError: [Errno 13] Permission denied: '/home/server/.local/share/virtualenvs/mainapp-c6pGQO_3/bin/activate_this.py'
[Sun Dec 05 13:32:24.256727 2021] [wsgi:error] [pid 14172:tid 140385016239872] [remote 192.168.1.237:51296] mod_wsgi (pid=14172): Target WSGI script '/var/www/mainapp/mainapp/mainapp.wsgi' cannot be loaded as Python module.
[Sun Dec 05 13:32:24.256771 2021] [wsgi:error] [pid 14172:tid 140385016239872] [remote 192.168.1.237:51296] mod_wsgi (pid=14172): Exception occurred processing WSGI script '/var/www/mainapp/mainapp/mainapp.wsgi'.
[Sun Dec 05 13:32:24.260049 2021] [wsgi:error] [pid 14172:tid 140385016239872] [remote 192.168.1.237:51296] Traceback (most recent call last):
[Sun Dec 05 13:32:24.260072 2021] [wsgi:error] [pid 14172:tid 140385016239872] [remote 192.168.1.237:51296]   File "/var/www/mainapp/mainapp/mainapp.wsgi", line 8, in <module>
[Sun Dec 05 13:32:24.260077 2021] [wsgi:error] [pid 14172:tid 140385016239872] [remote 192.168.1.237:51296]     with open(activate_this) as file_:
[Sun Dec 05 13:32:24.260088 2021] [wsgi:error] [pid 14172:tid 140385016239872] [remote 192.168.1.237:51296] PermissionError: [Errno 13] Permission denied: '/home/server/.local/share/virtualenvs/mainapp-c6pGQO_3/bin/activate_this.py'
[Sun Dec 05 13:32:27.710684 2021] [wsgi:error] [pid 14172:tid 140384991053568] [remote 192.168.1.237:51302] mod_wsgi (pid=14172): Target WSGI script '/var/www/mainapp/mainapp/mainapp.wsgi' cannot be loaded as Python module.
[Sun Dec 05 13:32:27.710842 2021] [wsgi:error] [pid 14172:tid 140384991053568] [remote 192.168.1.237:51302] mod_wsgi (pid=14172): Exception occurred processing WSGI script '/var/www/mainapp/mainapp/mainapp.wsgi'.
[Sun Dec 05 13:32:27.711054 2021] [wsgi:error] [pid 14172:tid 140384991053568] [remote 192.168.1.237:51302] Traceback (most recent call last):
[Sun Dec 05 13:32:27.711157 2021] [wsgi:error] [pid 14172:tid 140384991053568] [remote 192.168.1.237:51302]   File "/var/www/mainapp/mainapp/mainapp.wsgi", line 8, in <module>
[Sun Dec 05 13:32:27.711176 2021] [wsgi:error] [pid 14172:tid 140384991053568] [remote 192.168.1.237:51302]     with open(activate_this) as file_:
[Sun Dec 05 13:32:27.711222 2021] [wsgi:error] [pid 14172:tid 140384991053568] [remote 192.168.1.237:51302] PermissionError: [Errno 13] Permission denied: '/home/server/.local/share/virtualenvs/mainapp-c6pGQO_3/bin/activate_this.py'
[Sun Dec 05 13:32:30.863837 2021] [wsgi:error] [pid 14172:tid 140385016239872] [remote 192.168.1.237:51304] mod_wsgi (pid=14172): Target WSGI script '/var/www/mainapp/mainapp/mainapp.wsgi' cannot be loaded as Python module.
[Sun Dec 05 13:32:30.863971 2021] [wsgi:error] [pid 14172:tid 140385016239872] [remote 192.168.1.237:51304] mod_wsgi (pid=14172): Exception occurred processing WSGI script '/var/www/mainapp/mainapp/mainapp.wsgi'.
[Sun Dec 05 13:32:30.864175 2021] [wsgi:error] [pid 14172:tid 140385016239872] [remote 192.168.1.237:51304] Traceback (most recent call last):
[Sun Dec 05 13:32:30.864269 2021] [wsgi:error] [pid 14172:tid 140385016239872] [remote 192.168.1.237:51304]   File "/var/www/mainapp/mainapp/mainapp.wsgi", line 8, in <module>
[Sun Dec 05 13:32:30.864290 2021] [wsgi:error] [pid 14172:tid 140385016239872] [remote 192.168.1.237:51304]     with open(activate_this) as file_:
[Sun Dec 05 13:32:30.864339 2021] [wsgi:error] [pid 14172:tid 140385016239872] [remote 192.168.1.237:51304] PermissionError: [Errno 13] Permission denied: '/home/server/.local/share/virtualenvs/mainapp-c6pGQO_3/bin/activate_this.py'
[Sun Dec 05 13:36:11.672981 2021] [wsgi:error] [pid 14334:tid 140385016239872] [remote 192.168.1.237:51310] mod_wsgi (pid=14334): Target WSGI script '/var/www/mainapp/mainapp/mainapp.wsgi' cannot be loaded as Python module.
[Sun Dec 05 13:36:11.673157 2021] [wsgi:error] [pid 14334:tid 140385016239872] [remote 192.168.1.237:51310] mod_wsgi (pid=14334): Exception occurred processing WSGI script '/var/www/mainapp/mainapp/mainapp.wsgi'.
[Sun Dec 05 13:36:11.688965 2021] [wsgi:error] [pid 14334:tid 140385016239872] [remote 192.168.1.237:51310] Traceback (most recent call last):
[Sun Dec 05 13:36:11.689081 2021] [wsgi:error] [pid 14334:tid 140385016239872] [remote 192.168.1.237:51310]   File "/var/www/mainapp/mainapp/mainapp.wsgi", line 8, in <module>
[Sun Dec 05 13:36:11.689105 2021] [wsgi:error] [pid 14334:tid 140385016239872] [remote 192.168.1.237:51310]     with open(activate_this) as file_:
[Sun Dec 05 13:36:11.689165 2021] [wsgi:error] [pid 14334:tid 140385016239872] [remote 192.168.1.237:51310] PermissionError: [Errno 13] Permission denied: '/home/server/.local/share/virtualenvs/mainapp-c6pGQO_3/bin/activate_this.py'
[Sun Dec 05 13:38:32.472307 2021] [wsgi:error] [pid 14334:tid 140384982652672] [remote 192.168.1.237:51312] mod_wsgi (pid=14334): Target WSGI script '/var/www/mainapp/mainapp/mainapp.wsgi' cannot be loaded as Python module.
[Sun Dec 05 13:38:32.472464 2021] [wsgi:error] [pid 14334:tid 140384982652672] [remote 192.168.1.237:51312] mod_wsgi (pid=14334): Exception occurred processing WSGI script '/var/www/mainapp/mainapp/mainapp.wsgi'.
[Sun Dec 05 13:38:32.472663 2021] [wsgi:error] [pid 14334:tid 140384982652672] [remote 192.168.1.237:51312] Traceback (most recent call last):
[Sun Dec 05 13:38:32.472743 2021] [wsgi:error] [pid 14334:tid 140384982652672] [remote 192.168.1.237:51312]   File "/var/www/mainapp/mainapp/mainapp.wsgi", line 8, in <module>
[Sun Dec 05 13:38:32.472762 2021] [wsgi:error] [pid 14334:tid 140384982652672] [remote 192.168.1.237:51312]     with open(activate_this) as file_:
[Sun Dec 05 13:38:32.472809 2021] [wsgi:error] [pid 14334:tid 140384982652672] [remote 192.168.1.237:51312] PermissionError: [Errno 13] Permission denied: '/home/server/.local/share/virtualenvs/mainapp-c6pGQO_3/bin/activate_this.py'
[Sun Dec 05 14:25:10.337280 2021] [wsgi:error] [pid 15585:tid 140385016239872] [remote 192.168.1.237:51492] mod_wsgi (pid=15585): Target WSGI script '/var/www/mainapp/mainapp/mainapp.wsgi' cannot be loaded as Python module.
[Sun Dec 05 14:25:10.337332 2021] [wsgi:error] [pid 15585:tid 140385016239872] [remote 192.168.1.237:51492] mod_wsgi (pid=15585): Exception occurred processing WSGI script '/var/www/mainapp/mainapp/mainapp.wsgi'.
[Sun Dec 05 14:25:10.340694 2021] [wsgi:error] [pid 15585:tid 140385016239872] [remote 192.168.1.237:51492] Traceback (most recent call last):
[Sun Dec 05 14:25:10.341025 2021] [wsgi:error] [pid 15585:tid 140385016239872] [remote 192.168.1.237:51492]   File "/var/www/mainapp/mainapp/mainapp.wsgi", line 8, in <module>
[Sun Dec 05 14:25:10.341285 2021] [wsgi:error] [pid 15585:tid 140385016239872] [remote 192.168.1.237:51492]     with open(activate_this) as file_:
[Sun Dec 05 14:25:10.341534 2021] [wsgi:error] [pid 15585:tid 140385016239872] [remote 192.168.1.237:51492] PermissionError: [Errno 13] Permission denied: '/home/server/.local/share/virtualenvs/mainapp-c6pGQO_3/bin/activate_this.py'
[Sun Dec 05 14:25:14.190277 2021] [wsgi:error] [pid 15585:tid 140384991053568] [remote 192.168.1.237:51494] mod_wsgi (pid=15585): Target WSGI script '/var/www/mainapp/mainapp/mainapp.wsgi' cannot be loaded as Python module.
[Sun Dec 05 14:25:14.190437 2021] [wsgi:error] [pid 15585:tid 140384991053568] [remote 192.168.1.237:51494] mod_wsgi (pid=15585): Exception occurred processing WSGI script '/var/www/mainapp/mainapp/mainapp.wsgi'.
[Sun Dec 05 14:25:14.190702 2021] [wsgi:error] [pid 15585:tid 140384991053568] [remote 192.168.1.237:51494] Traceback (most recent call last):
[Sun Dec 05 14:25:14.190792 2021] [wsgi:error] [pid 15585:tid 140384991053568] [remote 192.168.1.237:51494]   File "/var/www/mainapp/mainapp/mainapp.wsgi", line 8, in <module>
[Sun Dec 05 14:25:14.190811 2021] [wsgi:error] [pid 15585:tid 140384991053568] [remote 192.168.1.237:51494]     with open(activate_this) as file_:
[Sun Dec 05 14:25:14.190863 2021] [wsgi:error] [pid 15585:tid 140384991053568] [remote 192.168.1.237:51494] PermissionError: [Errno 13] Permission denied: '/home/server/.local/share/virtualenvs/mainapp-c6pGQO_3/bin/activate_this.py'
[Sun Dec 05 14:25:15.630070 2021] [wsgi:error] [pid 15585:tid 140385016239872] [remote 192.168.1.237:51496] mod_wsgi (pid=15585): Target WSGI script '/var/www/mainapp/mainapp/mainapp.wsgi' cannot be loaded as Python module.
[Sun Dec 05 14:25:15.630218 2021] [wsgi:error] [pid 15585:tid 140385016239872] [remote 192.168.1.237:51496] mod_wsgi (pid=15585): Exception occurred processing WSGI script '/var/www/mainapp/mainapp/mainapp.wsgi'.
[Sun Dec 05 14:25:15.630420 2021] [wsgi:error] [pid 15585:tid 140385016239872] [remote 192.168.1.237:51496] Traceback (most recent call last):
[Sun Dec 05 14:25:15.630489 2021] [wsgi:error] [pid 15585:tid 140385016239872] [remote 192.168.1.237:51496]   File "/var/www/mainapp/mainapp/mainapp.wsgi", line 8, in <module>
[Sun Dec 05 14:25:15.630507 2021] [wsgi:error] [pid 15585:tid 140385016239872] [remote 192.168.1.237:51496]     with open(activate_this) as file_:
[Sun Dec 05 14:25:15.630553 2021] [wsgi:error] [pid 15585:tid 140385016239872] [remote 192.168.1.237:51496] PermissionError: [Errno 13] Permission denied: '/home/server/.local/share/virtualenvs/mainapp-c6pGQO_3/bin/activate_this.py'
[Sun Dec 05 14:25:19.687924 2021] [wsgi:error] [pid 15585:tid 140384991053568] [remote 192.168.1.237:51498] mod_wsgi (pid=15585): Target WSGI script '/var/www/mainapp/mainapp/mainapp.wsgi' cannot be loaded as Python module.
[Sun Dec 05 14:25:19.688053 2021] [wsgi:error] [pid 15585:tid 140384991053568] [remote 192.168.1.237:51498] mod_wsgi (pid=15585): Exception occurred processing WSGI script '/var/www/mainapp/mainapp/mainapp.wsgi'.
[Sun Dec 05 14:25:19.688273 2021] [wsgi:error] [pid 15585:tid 140384991053568] [remote 192.168.1.237:51498] Traceback (most recent call last):
[Sun Dec 05 14:25:19.688348 2021] [wsgi:error] [pid 15585:tid 140384991053568] [remote 192.168.1.237:51498]   File "/var/www/mainapp/mainapp/mainapp.wsgi", line 8, in <module>
[Sun Dec 05 14:25:19.688367 2021] [wsgi:error] [pid 15585:tid 140384991053568] [remote 192.168.1.237:51498]     with open(activate_this) as file_:
[Sun Dec 05 14:25:19.688437 2021] [wsgi:error] [pid 15585:tid 140384991053568] [remote 192.168.1.237:51498] PermissionError: [Errno 13] Permission denied: '/home/server/.local/share/virtualenvs/mainapp-c6pGQO_3/bin/activate_this.py'
[Sun Dec 05 15:41:10.313452 2021] [wsgi:error] [pid 15585:tid 140385016239872] [remote 192.168.1.237:51894] mod_wsgi (pid=15585): Target WSGI script '/var/www/mainapp/mainapp/mainapp.wsgi' cannot be loaded as Python module.
[Sun Dec 05 15:41:10.313550 2021] [wsgi:error] [pid 15585:tid 140385016239872] [remote 192.168.1.237:51894] mod_wsgi (pid=15585): Exception occurred processing WSGI script '/var/www/mainapp/mainapp/mainapp.wsgi'.
[Sun Dec 05 15:41:10.313700 2021] [wsgi:error] [pid 15585:tid 140385016239872] [remote 192.168.1.237:51894] Traceback (most recent call last):
[Sun Dec 05 15:41:10.313752 2021] [wsgi:error] [pid 15585:tid 140385016239872] [remote 192.168.1.237:51894]   File "/var/www/mainapp/mainapp/mainapp.wsgi", line 8, in <module>
[Sun Dec 05 15:41:10.313766 2021] [wsgi:error] [pid 15585:tid 140385016239872] [remote 192.168.1.237:51894]     with open(activate_this) as file_:
[Sun Dec 05 15:41:10.313801 2021] [wsgi:error] [pid 15585:tid 140385016239872] [remote 192.168.1.237:51894] PermissionError: [Errno 13] Permission denied: '/home/server/.local/share/virtualenvs/mainapp-c6pGQO_3/bin/activate_this.py'
[Sun Dec 05 15:47:07.134772 2021] [wsgi:error] [pid 16695:tid 140385016239872] [remote 192.168.1.237:51948] mod_wsgi (pid=16695): Target WSGI script '/var/www/mainapp/mainapp/mainapp.wsgi' cannot be loaded as Python module.
[Sun Dec 05 15:47:07.134944 2021] [wsgi:error] [pid 16695:tid 140385016239872] [remote 192.168.1.237:51948] mod_wsgi (pid=16695): Exception occurred processing WSGI script '/var/www/mainapp/mainapp/mainapp.wsgi'.
[Sun Dec 05 15:47:07.151164 2021] [wsgi:error] [pid 16695:tid 140385016239872] [remote 192.168.1.237:51948] Traceback (most recent call last):
[Sun Dec 05 15:47:07.151321 2021] [wsgi:error] [pid 16695:tid 140385016239872] [remote 192.168.1.237:51948]   File "/var/www/mainapp/mainapp/mainapp.wsgi", line 8, in <module>
[Sun Dec 05 15:47:07.151345 2021] [wsgi:error] [pid 16695:tid 140385016239872] [remote 192.168.1.237:51948]     exec(open(activate_this).read(), {'__file__': activate_this})
[Sun Dec 05 15:47:07.151407 2021] [wsgi:error] [pid 16695:tid 140385016239872] [remote 192.168.1.237:51948] PermissionError: [Errno 13] Permission denied: '/home/server/.local/share/virtualenvs/mainapp-c6pGQO_3/bin/activate_this.py'
[Sun Dec 05 15:47:08.381168 2021] [wsgi:error] [pid 16695:tid 140384982652672] [remote 192.168.1.237:51950] mod_wsgi (pid=16695): Target WSGI script '/var/www/mainapp/mainapp/mainapp.wsgi' cannot be loaded as Python module.
[Sun Dec 05 15:47:08.381326 2021] [wsgi:error] [pid 16695:tid 140384982652672] [remote 192.168.1.237:51950] mod_wsgi (pid=16695): Exception occurred processing WSGI script '/var/www/mainapp/mainapp/mainapp.wsgi'.
[Sun Dec 05 15:47:08.381525 2021] [wsgi:error] [pid 16695:tid 140384982652672] [remote 192.168.1.237:51950] Traceback (most recent call last):
[Sun Dec 05 15:47:08.381604 2021] [wsgi:error] [pid 16695:tid 140384982652672] [remote 192.168.1.237:51950]   File "/var/www/mainapp/mainapp/mainapp.wsgi", line 8, in <module>
[Sun Dec 05 15:47:08.381624 2021] [wsgi:error] [pid 16695:tid 140384982652672] [remote 192.168.1.237:51950]     exec(open(activate_this).read(), {'__file__': activate_this})
[Sun Dec 05 15:47:08.381671 2021] [wsgi:error] [pid 16695:tid 140384982652672] [remote 192.168.1.237:51950] PermissionError: [Errno 13] Permission denied: '/home/server/.local/share/virtualenvs/mainapp-c6pGQO_3/bin/activate_this.py'
[Sun Dec 05 15:47:09.499993 2021] [wsgi:error] [pid 16695:tid 140385016239872] [remote 192.168.1.237:51952] mod_wsgi (pid=16695): Target WSGI script '/var/www/mainapp/mainapp/mainapp.wsgi' cannot be loaded as Python module.
[Sun Dec 05 15:47:09.500122 2021] [wsgi:error] [pid 16695:tid 140385016239872] [remote 192.168.1.237:51952] mod_wsgi (pid=16695): Exception occurred processing WSGI script '/var/www/mainapp/mainapp/mainapp.wsgi'.
[Sun Dec 05 15:47:09.500368 2021] [wsgi:error] [pid 16695:tid 140385016239872] [remote 192.168.1.237:51952] Traceback (most recent call last):
[Sun Dec 05 15:47:09.500439 2021] [wsgi:error] [pid 16695:tid 140385016239872] [remote 192.168.1.237:51952]   File "/var/www/mainapp/mainapp/mainapp.wsgi", line 8, in <module>
[Sun Dec 05 15:47:09.500457 2021] [wsgi:error] [pid 16695:tid 140385016239872] [remote 192.168.1.237:51952]     exec(open(activate_this).read(), {'__file__': activate_this})
[Sun Dec 05 15:47:09.500500 2021] [wsgi:error] [pid 16695:tid 140385016239872] [remote 192.168.1.237:51952] PermissionError: [Errno 13] Permission denied: '/home/server/.local/share/virtualenvs/mainapp-c6pGQO_3/bin/activate_this.py'
[Sun Dec 05 15:59:25.073253 2021] [wsgi:error] [pid 17068:tid 140385007847168] [remote 192.168.1.237:52038] mod_wsgi (pid=17068): Target WSGI script '/var/www/mainapp/mainapp/mainapp.wsgi' cannot be loaded as Python module.
[Sun Dec 05 15:59:25.073430 2021] [wsgi:error] [pid 17068:tid 140385007847168] [remote 192.168.1.237:52038] mod_wsgi (pid=17068): Exception occurred processing WSGI script '/var/www/mainapp/mainapp/mainapp.wsgi'.
[Sun Dec 05 15:59:25.087082 2021] [wsgi:error] [pid 17068:tid 140385007847168] [remote 192.168.1.237:52038] Traceback (most recent call last):
[Sun Dec 05 15:59:25.087166 2021] [wsgi:error] [pid 17068:tid 140385007847168] [remote 192.168.1.237:52038]   File "/var/www/mainapp/mainapp/mainapp.wsgi", line 8, in <module>
[Sun Dec 05 15:59:25.087182 2021] [wsgi:error] [pid 17068:tid 140385007847168] [remote 192.168.1.237:52038]     exec(open(activate_this).read(), {'__file__': activate_this})
[Sun Dec 05 15:59:25.087223 2021] [wsgi:error] [pid 17068:tid 140385007847168] [remote 192.168.1.237:52038] PermissionError: [Errno 13] Permission denied: '/home/server/.local/share/virtualenvs/mainapp-c6pGQO_3/bin/activate_this.py'
[Sun Dec 05 15:59:26.352763 2021] [wsgi:error] [pid 17068:tid 140384991053568] [remote 192.168.1.237:52040] mod_wsgi (pid=17068): Target WSGI script '/var/www/mainapp/mainapp/mainapp.wsgi' cannot be loaded as Python module.
[Sun Dec 05 15:59:26.352925 2021] [wsgi:error] [pid 17068:tid 140384991053568] [remote 192.168.1.237:52040] mod_wsgi (pid=17068): Exception occurred processing WSGI script '/var/www/mainapp/mainapp/mainapp.wsgi'.
[Sun Dec 05 15:59:26.353128 2021] [wsgi:error] [pid 17068:tid 140384991053568] [remote 192.168.1.237:52040] Traceback (most recent call last):
[Sun Dec 05 15:59:26.353209 2021] [wsgi:error] [pid 17068:tid 140384991053568] [remote 192.168.1.237:52040]   File "/var/www/mainapp/mainapp/mainapp.wsgi", line 8, in <module>
[Sun Dec 05 15:59:26.353228 2021] [wsgi:error] [pid 17068:tid 140384991053568] [remote 192.168.1.237:52040]     exec(open(activate_this).read(), {'__file__': activate_this})
[Sun Dec 05 15:59:26.353275 2021] [wsgi:error] [pid 17068:tid 140384991053568] [remote 192.168.1.237:52040] PermissionError: [Errno 13] Permission denied: '/home/server/.local/share/virtualenvs/mainapp-c6pGQO_3/bin/activate_this.py'
[Sun Dec 05 16:04:15.237917 2021] [wsgi:error] [pid 17227:tid 140385007847168] [remote 192.168.1.237:52046] mod_wsgi (pid=17227): Target WSGI script '/var/www/mainapp/mainapp/mainapp.wsgi' cannot be loaded as Python module.
[Sun Dec 05 16:04:15.238100 2021] [wsgi:error] [pid 17227:tid 140385007847168] [remote 192.168.1.237:52046] mod_wsgi (pid=17227): Exception occurred processing WSGI script '/var/www/mainapp/mainapp/mainapp.wsgi'.
[Sun Dec 05 16:04:15.254904 2021] [wsgi:error] [pid 17227:tid 140385007847168] [remote 192.168.1.237:52046] Traceback (most recent call last):
[Sun Dec 05 16:04:15.255029 2021] [wsgi:error] [pid 17227:tid 140385007847168] [remote 192.168.1.237:52046]   File "/var/www/mainapp/mainapp/mainapp.wsgi", line 8, in <module>
[Sun Dec 05 16:04:15.255052 2021] [wsgi:error] [pid 17227:tid 140385007847168] [remote 192.168.1.237:52046]     exec(open(activate_this).read(), {'__file__': activate_this})
[Sun Dec 05 16:04:15.255139 2021] [wsgi:error] [pid 17227:tid 140385007847168] [remote 192.168.1.237:52046] PermissionError: [Errno 13] Permission denied: '/home/server/.local/share/virtualenvs/mainapp-c6pGQO_3/bin/activate_this.py'
[Sun Dec 05 16:04:17.909535 2021] [wsgi:error] [pid 17227:tid 140384982652672] [remote 192.168.1.237:52048] mod_wsgi (pid=17227): Target WSGI script '/var/www/mainapp/mainapp/mainapp.wsgi' cannot be loaded as Python module.
[Sun Dec 05 16:04:17.909579 2021] [wsgi:error] [pid 17227:tid 140384982652672] [remote 192.168.1.237:52048] mod_wsgi (pid=17227): Exception occurred processing WSGI script '/var/www/mainapp/mainapp/mainapp.wsgi'.
[Sun Dec 05 16:04:17.909639 2021] [wsgi:error] [pid 17227:tid 140384982652672] [remote 192.168.1.237:52048] Traceback (most recent call last):
[Sun Dec 05 16:04:17.909658 2021] [wsgi:error] [pid 17227:tid 140384982652672] [remote 192.168.1.237:52048]   File "/var/www/mainapp/mainapp/mainapp.wsgi", line 8, in <module>
[Sun Dec 05 16:04:17.909662 2021] [wsgi:error] [pid 17227:tid 140384982652672] [remote 192.168.1.237:52048]     exec(open(activate_this).read(), {'__file__': activate_this})
[Sun Dec 05 16:04:17.909676 2021] [wsgi:error] [pid 17227:tid 140384982652672] [remote 192.168.1.237:52048] PermissionError: [Errno 13] Permission denied: '/home/server/.local/share/virtualenvs/mainapp-c6pGQO_3/bin/activate_this.py'
[Sun Dec 05 16:04:31.220151 2021] [wsgi:error] [pid 17227:tid 140385007847168] [remote 192.168.1.237:52050] mod_wsgi (pid=17227): Target WSGI script '/var/www/mainapp/mainapp/mainapp.wsgi' cannot be loaded as Python module.
[Sun Dec 05 16:04:31.220254 2021] [wsgi:error] [pid 17227:tid 140385007847168] [remote 192.168.1.237:52050] mod_wsgi (pid=17227): Exception occurred processing WSGI script '/var/www/mainapp/mainapp/mainapp.wsgi'.
[Sun Dec 05 16:04:31.220373 2021] [wsgi:error] [pid 17227:tid 140385007847168] [remote 192.168.1.237:52050] Traceback (most recent call last):
[Sun Dec 05 16:04:31.220411 2021] [wsgi:error] [pid 17227:tid 140385007847168] [remote 192.168.1.237:52050]   File "/var/www/mainapp/mainapp/mainapp.wsgi", line 8, in <module>
[Sun Dec 05 16:04:31.220421 2021] [wsgi:error] [pid 17227:tid 140385007847168] [remote 192.168.1.237:52050]     exec(open(activate_this).read(), {'__file__': activate_this})
[Sun Dec 05 16:04:31.220447 2021] [wsgi:error] [pid 17227:tid 140385007847168] [remote 192.168.1.237:52050] PermissionError: [Errno 13] Permission denied: '/home/server/.local/share/virtualenvs/mainapp-c6pGQO_3/bin/activate_this.py'
[Sun Dec 05 16:04:31.248945 2021] [wsgi:error] [pid 17227:tid 140384982652672] [remote 192.168.1.237:52052] mod_wsgi (pid=17227): Target WSGI script '/var/www/mainapp/mainapp/mainapp.wsgi' cannot be loaded as Python module.
[Sun Dec 05 16:04:31.248977 2021] [wsgi:error] [pid 17227:tid 140384982652672] [remote 192.168.1.237:52052] mod_wsgi (pid=17227): Exception occurred processing WSGI script '/var/www/mainapp/mainapp/mainapp.wsgi'.
[Sun Dec 05 16:04:31.249033 2021] [wsgi:error] [pid 17227:tid 140384982652672] [remote 192.168.1.237:52052] Traceback (most recent call last):
[Sun Dec 05 16:04:31.249049 2021] [wsgi:error] [pid 17227:tid 140384982652672] [remote 192.168.1.237:52052]   File "/var/www/mainapp/mainapp/mainapp.wsgi", line 8, in <module>
[Sun Dec 05 16:04:31.249053 2021] [wsgi:error] [pid 17227:tid 140384982652672] [remote 192.168.1.237:52052]     exec(open(activate_this).read(), {'__file__': activate_this})
[Sun Dec 05 16:04:31.249063 2021] [wsgi:error] [pid 17227:tid 140384982652672] [remote 192.168.1.237:52052] PermissionError: [Errno 13] Permission denied: '/home/server/.local/share/virtualenvs/mainapp-c6pGQO_3/bin/activate_this.py'
[Sun Dec 05 17:15:51.945050 2021] [wsgi:error] [pid 19306:tid 139913476060928] [remote 192.168.1.237:52770] mod_wsgi (pid=19306): Target WSGI script '/var/www/mainapp/mainapp/mainapp.wsgi' cannot be loaded as Python module.
[Sun Dec 05 17:15:51.945113 2021] [wsgi:error] [pid 19306:tid 139913476060928] [remote 192.168.1.237:52770] mod_wsgi (pid=19306): Exception occurred processing WSGI script '/var/www/mainapp/mainapp/mainapp.wsgi'.
[Sun Dec 05 17:15:51.948618 2021] [wsgi:error] [pid 19306:tid 139913476060928] [remote 192.168.1.237:52770] Traceback (most recent call last):
[Sun Dec 05 17:15:51.948651 2021] [wsgi:error] [pid 19306:tid 139913476060928] [remote 192.168.1.237:52770]   File "/var/www/mainapp/mainapp/mainapp.wsgi", line 8, in <module>
[Sun Dec 05 17:15:51.948655 2021] [wsgi:error] [pid 19306:tid 139913476060928] [remote 192.168.1.237:52770]     exec(open(activate_this).read(), {'__file__': activate_this})
[Sun Dec 05 17:15:51.948668 2021] [wsgi:error] [pid 19306:tid 139913476060928] [remote 192.168.1.237:52770] PermissionError: [Errno 13] Permission denied: '/home/server/.local/share/virtualenvs/mainapp-c6pGQO_3/bin/activate_this.py'
[Sun Dec 05 17:15:54.680733 2021] [wsgi:error] [pid 19306:tid 139913442490112] [remote 192.168.1.237:52772] mod_wsgi (pid=19306): Target WSGI script '/var/www/mainapp/mainapp/mainapp.wsgi' cannot be loaded as Python module.
[Sun Dec 05 17:15:54.680780 2021] [wsgi:error] [pid 19306:tid 139913442490112] [remote 192.168.1.237:52772] mod_wsgi (pid=19306): Exception occurred processing WSGI script '/var/www/mainapp/mainapp/mainapp.wsgi'.
[Sun Dec 05 17:15:54.680838 2021] [wsgi:error] [pid 19306:tid 139913442490112] [remote 192.168.1.237:52772] Traceback (most recent call last):
[Sun Dec 05 17:15:54.680857 2021] [wsgi:error] [pid 19306:tid 139913442490112] [remote 192.168.1.237:52772]   File "/var/www/mainapp/mainapp/mainapp.wsgi", line 8, in <module>
[Sun Dec 05 17:15:54.680861 2021] [wsgi:error] [pid 19306:tid 139913442490112] [remote 192.168.1.237:52772]     exec(open(activate_this).read(), {'__file__': activate_this})
[Sun Dec 05 17:15:54.680872 2021] [wsgi:error] [pid 19306:tid 139913442490112] [remote 192.168.1.237:52772] PermissionError: [Errno 13] Permission denied: '/home/server/.local/share/virtualenvs/mainapp-c6pGQO_3/bin/activate_this.py'
[Sun Dec 05 17:15:55.918044 2021] [wsgi:error] [pid 19306:tid 139913476060928] [remote 192.168.1.237:52774] mod_wsgi (pid=19306): Target WSGI script '/var/www/mainapp/mainapp/mainapp.wsgi' cannot be loaded as Python module.
[Sun Dec 05 17:15:55.918084 2021] [wsgi:error] [pid 19306:tid 139913476060928] [remote 192.168.1.237:52774] mod_wsgi (pid=19306): Exception occurred processing WSGI script '/var/www/mainapp/mainapp/mainapp.wsgi'.
[Sun Dec 05 17:15:55.918144 2021] [wsgi:error] [pid 19306:tid 139913476060928] [remote 192.168.1.237:52774] Traceback (most recent call last):
[Sun Dec 05 17:15:55.918159 2021] [wsgi:error] [pid 19306:tid 139913476060928] [remote 192.168.1.237:52774]   File "/var/www/mainapp/mainapp/mainapp.wsgi", line 8, in <module>
[Sun Dec 05 17:15:55.918163 2021] [wsgi:error] [pid 19306:tid 139913476060928] [remote 192.168.1.237:52774]     exec(open(activate_this).read(), {'__file__': activate_this})
[Sun Dec 05 17:15:55.918173 2021] [wsgi:error] [pid 19306:tid 139913476060928] [remote 192.168.1.237:52774] PermissionError: [Errno 13] Permission denied: '/home/server/.local/share/virtualenvs/mainapp-c6pGQO_3/bin/activate_this.py'
[Sun Dec 05 17:24:11.062712 2021] [wsgi:error] [pid 21020:tid 140002797500160] [remote 192.168.1.237:53456] mod_wsgi (pid=21020): Target WSGI script '/var/www/mainapp/mainapp/mainapp.wsgi' cannot be loaded as Python module.
[Sun Dec 05 17:24:11.062955 2021] [wsgi:error] [pid 21020:tid 140002797500160] [remote 192.168.1.237:53456] mod_wsgi (pid=21020): Exception occurred processing WSGI script '/var/www/mainapp/mainapp/mainapp.wsgi'.
[Sun Dec 05 17:24:11.077062 2021] [wsgi:error] [pid 21020:tid 140002797500160] [remote 192.168.1.237:53456] Traceback (most recent call last):
[Sun Dec 05 17:24:11.077148 2021] [wsgi:error] [pid 21020:tid 140002797500160] [remote 192.168.1.237:53456]   File "/var/www/mainapp/mainapp/mainapp.wsgi", line 8, in <module>
[Sun Dec 05 17:24:11.077164 2021] [wsgi:error] [pid 21020:tid 140002797500160] [remote 192.168.1.237:53456]     exec(open(activate_this).read(), {'__file__': activate_this})
[Sun Dec 05 17:24:11.077224 2021] [wsgi:error] [pid 21020:tid 140002797500160] [remote 192.168.1.237:53456] PermissionError: [Errno 13] Permission denied: '/home/server/.local/share/virtualenvs/mainapp-c6pGQO_3/bin/activate_this.py'
[Sun Dec 05 17:24:12.340340 2021] [wsgi:error] [pid 21020:tid 140002763929344] [remote 192.168.1.237:53458] mod_wsgi (pid=21020): Target WSGI script '/var/www/mainapp/mainapp/mainapp.wsgi' cannot be loaded as Python module.
[Sun Dec 05 17:24:12.340500 2021] [wsgi:error] [pid 21020:tid 140002763929344] [remote 192.168.1.237:53458] mod_wsgi (pid=21020): Exception occurred processing WSGI script '/var/www/mainapp/mainapp/mainapp.wsgi'.
[Sun Dec 05 17:24:12.340707 2021] [wsgi:error] [pid 21020:tid 140002763929344] [remote 192.168.1.237:53458] Traceback (most recent call last):
[Sun Dec 05 17:24:12.340787 2021] [wsgi:error] [pid 21020:tid 140002763929344] [remote 192.168.1.237:53458]   File "/var/www/mainapp/mainapp/mainapp.wsgi", line 8, in <module>
[Sun Dec 05 17:24:12.340805 2021] [wsgi:error] [pid 21020:tid 140002763929344] [remote 192.168.1.237:53458]     exec(open(activate_this).read(), {'__file__': activate_this})
[Sun Dec 05 17:24:12.340852 2021] [wsgi:error] [pid 21020:tid 140002763929344] [remote 192.168.1.237:53458] PermissionError: [Errno 13] Permission denied: '/home/server/.local/share/virtualenvs/mainapp-c6pGQO_3/bin/activate_this.py'
[Sun Dec 05 17:24:19.545295 2021] [wsgi:error] [pid 21020:tid 140002797500160] [remote 192.168.1.237:53464] mod_wsgi (pid=21020): Target WSGI script '/var/www/mainapp/mainapp/mainapp.wsgi' cannot be loaded as Python module.
[Sun Dec 05 17:24:19.545425 2021] [wsgi:error] [pid 21020:tid 140002797500160] [remote 192.168.1.237:53464] mod_wsgi (pid=21020): Exception occurred processing WSGI script '/var/www/mainapp/mainapp/mainapp.wsgi'.
[Sun Dec 05 17:24:19.545621 2021] [wsgi:error] [pid 21020:tid 140002797500160] [remote 192.168.1.237:53464] Traceback (most recent call last):
[Sun Dec 05 17:24:19.545694 2021] [wsgi:error] [pid 21020:tid 140002797500160] [remote 192.168.1.237:53464]   File "/var/www/mainapp/mainapp/mainapp.wsgi", line 8, in <module>
[Sun Dec 05 17:24:19.545713 2021] [wsgi:error] [pid 21020:tid 140002797500160] [remote 192.168.1.237:53464]     exec(open(activate_this).read(), {'__file__': activate_this})
[Sun Dec 05 17:24:19.545757 2021] [wsgi:error] [pid 21020:tid 140002797500160] [remote 192.168.1.237:53464] PermissionError: [Errno 13] Permission denied: '/home/server/.local/share/virtualenvs/mainapp-c6pGQO_3/bin/activate_this.py'
[Sun Dec 05 17:24:39.651843 2021] [wsgi:error] [pid 21020:tid 140002763929344] [remote 192.168.1.237:53466] mod_wsgi (pid=21020): Target WSGI script '/var/www/mainapp/mainapp/mainapp.wsgi' cannot be loaded as Python module.
[Sun Dec 05 17:24:39.651983 2021] [wsgi:error] [pid 21020:tid 140002763929344] [remote 192.168.1.237:53466] mod_wsgi (pid=21020): Exception occurred processing WSGI script '/var/www/mainapp/mainapp/mainapp.wsgi'.
[Sun Dec 05 17:24:39.652184 2021] [wsgi:error] [pid 21020:tid 140002763929344] [remote 192.168.1.237:53466] Traceback (most recent call last):
[Sun Dec 05 17:24:39.652257 2021] [wsgi:error] [pid 21020:tid 140002763929344] [remote 192.168.1.237:53466]   File "/var/www/mainapp/mainapp/mainapp.wsgi", line 8, in <module>
[Sun Dec 05 17:24:39.652275 2021] [wsgi:error] [pid 21020:tid 140002763929344] [remote 192.168.1.237:53466]     exec(open(activate_this).read(), {'__file__': activate_this})
[Sun Dec 05 17:24:39.652311 2021] [wsgi:error] [pid 21020:tid 140002763929344] [remote 192.168.1.237:53466] PermissionError: [Errno 13] Permission denied: '/home/server/.local/share/virtualenvs/mainapp-c6pGQO_3/bin/activate_this.py'
[Sun Dec 05 17:24:39.680802 2021] [wsgi:error] [pid 21020:tid 140002797500160] [remote 192.168.1.237:53468] mod_wsgi (pid=21020): Target WSGI script '/var/www/mainapp/mainapp/mainapp.wsgi' cannot be loaded as Python module.
[Sun Dec 05 17:24:39.680859 2021] [wsgi:error] [pid 21020:tid 140002797500160] [remote 192.168.1.237:53468] mod_wsgi (pid=21020): Exception occurred processing WSGI script '/var/www/mainapp/mainapp/mainapp.wsgi'.
[Sun Dec 05 17:24:39.680971 2021] [wsgi:error] [pid 21020:tid 140002797500160] [remote 192.168.1.237:53468] Traceback (most recent call last):
[Sun Dec 05 17:24:39.681005 2021] [wsgi:error] [pid 21020:tid 140002797500160] [remote 192.168.1.237:53468]   File "/var/www/mainapp/mainapp/mainapp.wsgi", line 8, in <module>
[Sun Dec 05 17:24:39.681013 2021] [wsgi:error] [pid 21020:tid 140002797500160] [remote 192.168.1.237:53468]     exec(open(activate_this).read(), {'__file__': activate_this})
[Sun Dec 05 17:24:39.681035 2021] [wsgi:error] [pid 21020:tid 140002797500160] [remote 192.168.1.237:53468] PermissionError: [Errno 13] Permission denied: '/home/server/.local/share/virtualenvs/mainapp-c6pGQO_3/bin/activate_this.py'
[Sun Dec 05 17:24:42.066138 2021] [wsgi:error] [pid 21020:tid 140002763929344] [remote 192.168.1.237:53470] mod_wsgi (pid=21020): Target WSGI script '/var/www/mainapp/mainapp/mainapp.wsgi' cannot be loaded as Python module.
[Sun Dec 05 17:24:42.066278 2021] [wsgi:error] [pid 21020:tid 140002763929344] [remote 192.168.1.237:53470] mod_wsgi (pid=21020): Exception occurred processing WSGI script '/var/www/mainapp/mainapp/mainapp.wsgi'.
[Sun Dec 05 17:24:42.066479 2021] [wsgi:error] [pid 21020:tid 140002763929344] [remote 192.168.1.237:53470] Traceback (most recent call last):
[Sun Dec 05 17:24:42.066547 2021] [wsgi:error] [pid 21020:tid 140002763929344] [remote 192.168.1.237:53470]   File "/var/www/mainapp/mainapp/mainapp.wsgi", line 8, in <module>
[Sun Dec 05 17:24:42.066565 2021] [wsgi:error] [pid 21020:tid 140002763929344] [remote 192.168.1.237:53470]     exec(open(activate_this).read(), {'__file__': activate_this})
[Sun Dec 05 17:24:42.066610 2021] [wsgi:error] [pid 21020:tid 140002763929344] [remote 192.168.1.237:53470] PermissionError: [Errno 13] Permission denied: '/home/server/.local/share/virtualenvs/mainapp-c6pGQO_3/bin/activate_this.py'
[Sun Dec 05 17:44:42.372122 2021] [wsgi:error] [pid 21399:tid 140555088631552] [remote 192.168.1.237:53762] mod_wsgi (pid=21399): Target WSGI script '/var/www/mainapp/mainapp/mainapp.wsgi' cannot be loaded as Python module.
[Sun Dec 05 17:44:42.372404 2021] [wsgi:error] [pid 21399:tid 140555088631552] [remote 192.168.1.237:53762] mod_wsgi (pid=21399): Exception occurred processing WSGI script '/var/www/mainapp/mainapp/mainapp.wsgi'.
[Sun Dec 05 17:44:42.388544 2021] [wsgi:error] [pid 21399:tid 140555088631552] [remote 192.168.1.237:53762] Traceback (most recent call last):
[Sun Dec 05 17:44:42.388675 2021] [wsgi:error] [pid 21399:tid 140555088631552] [remote 192.168.1.237:53762]   File "/var/www/mainapp/mainapp/mainapp.wsgi", line 8, in <module>
[Sun Dec 05 17:44:42.388695 2021] [wsgi:error] [pid 21399:tid 140555088631552] [remote 192.168.1.237:53762]     exec(open(activate_this).read(), {'__file__': activate_this})
[Sun Dec 05 17:44:42.388755 2021] [wsgi:error] [pid 21399:tid 140555088631552] [remote 192.168.1.237:53762] PermissionError: [Errno 13] Permission denied: '/home/server/.local/share/virtualenvs/mainapp-c6pGQO_3/bin/activate_this.py'
[Sun Dec 05 17:44:43.745954 2021] [wsgi:error] [pid 21399:tid 140555063453440] [remote 192.168.1.237:53764] mod_wsgi (pid=21399): Target WSGI script '/var/www/mainapp/mainapp/mainapp.wsgi' cannot be loaded as Python module.
[Sun Dec 05 17:44:43.746163 2021] [wsgi:error] [pid 21399:tid 140555063453440] [remote 192.168.1.237:53764] mod_wsgi (pid=21399): Exception occurred processing WSGI script '/var/www/mainapp/mainapp/mainapp.wsgi'.
[Sun Dec 05 17:44:43.746419 2021] [wsgi:error] [pid 21399:tid 140555063453440] [remote 192.168.1.237:53764] Traceback (most recent call last):
[Sun Dec 05 17:44:43.746512 2021] [wsgi:error] [pid 21399:tid 140555063453440] [remote 192.168.1.237:53764]   File "/var/www/mainapp/mainapp/mainapp.wsgi", line 8, in <module>
[Sun Dec 05 17:44:43.746532 2021] [wsgi:error] [pid 21399:tid 140555063453440] [remote 192.168.1.237:53764]     exec(open(activate_this).read(), {'__file__': activate_this})
[Sun Dec 05 17:44:43.746587 2021] [wsgi:error] [pid 21399:tid 140555063453440] [remote 192.168.1.237:53764] PermissionError: [Errno 13] Permission denied: '/home/server/.local/share/virtualenvs/mainapp-c6pGQO_3/bin/activate_this.py'
[Sun Dec 05 17:44:48.062657 2021] [wsgi:error] [pid 21399:tid 140555088631552] [remote 192.168.1.237:53770] mod_wsgi (pid=21399): Target WSGI script '/var/www/mainapp/mainapp/mainapp.wsgi' cannot be loaded as Python module.
[Sun Dec 05 17:44:48.062787 2021] [wsgi:error] [pid 21399:tid 140555088631552] [remote 192.168.1.237:53770] mod_wsgi (pid=21399): Exception occurred processing WSGI script '/var/www/mainapp/mainapp/mainapp.wsgi'.
[Sun Dec 05 17:44:48.062986 2021] [wsgi:error] [pid 21399:tid 140555088631552] [remote 192.168.1.237:53770] Traceback (most recent call last):
[Sun Dec 05 17:44:48.063054 2021] [wsgi:error] [pid 21399:tid 140555088631552] [remote 192.168.1.237:53770]   File "/var/www/mainapp/mainapp/mainapp.wsgi", line 8, in <module>
[Sun Dec 05 17:44:48.063072 2021] [wsgi:error] [pid 21399:tid 140555088631552] [remote 192.168.1.237:53770]     exec(open(activate_this).read(), {'__file__': activate_this})
[Sun Dec 05 17:44:48.063118 2021] [wsgi:error] [pid 21399:tid 140555088631552] [remote 192.168.1.237:53770] PermissionError: [Errno 13] Permission denied: '/home/server/.local/share/virtualenvs/mainapp-c6pGQO_3/bin/activate_this.py'
[Sun Dec 05 17:44:55.052003 2021] [wsgi:error] [pid 21399:tid 140555063453440] [remote 192.168.1.237:53772] mod_wsgi (pid=21399): Target WSGI script '/var/www/mainapp/mainapp/mainapp.wsgi' cannot be loaded as Python module.
[Sun Dec 05 17:44:55.052058 2021] [wsgi:error] [pid 21399:tid 140555063453440] [remote 192.168.1.237:53772] mod_wsgi (pid=21399): Exception occurred processing WSGI script '/var/www/mainapp/mainapp/mainapp.wsgi'.
[Sun Dec 05 17:44:55.052135 2021] [wsgi:error] [pid 21399:tid 140555063453440] [remote 192.168.1.237:53772] Traceback (most recent call last):
[Sun Dec 05 17:44:55.052160 2021] [wsgi:error] [pid 21399:tid 140555063453440] [remote 192.168.1.237:53772]   File "/var/www/mainapp/mainapp/mainapp.wsgi", line 8, in <module>
[Sun Dec 05 17:44:55.052163 2021] [wsgi:error] [pid 21399:tid 140555063453440] [remote 192.168.1.237:53772]     exec(open(activate_this).read(), {'__file__': activate_this})
[Sun Dec 05 17:44:55.052184 2021] [wsgi:error] [pid 21399:tid 140555063453440] [remote 192.168.1.237:53772] PermissionError: [Errno 13] Permission denied: '/home/server/.local/share/virtualenvs/mainapp-c6pGQO_3/bin/activate_this.py'
[Sun Dec 05 17:45:00.221146 2021] [wsgi:error] [pid 21399:tid 140555088631552] [remote 192.168.1.237:53774] mod_wsgi (pid=21399): Target WSGI script '/var/www/mainapp/mainapp/mainapp.wsgi' cannot be loaded as Python module.
[Sun Dec 05 17:45:00.221284 2021] [wsgi:error] [pid 21399:tid 140555088631552] [remote 192.168.1.237:53774] mod_wsgi (pid=21399): Exception occurred processing WSGI script '/var/www/mainapp/mainapp/mainapp.wsgi'.
[Sun Dec 05 17:45:00.221487 2021] [wsgi:error] [pid 21399:tid 140555088631552] [remote 192.168.1.237:53774] Traceback (most recent call last):
[Sun Dec 05 17:45:00.221557 2021] [wsgi:error] [pid 21399:tid 140555088631552] [remote 192.168.1.237:53774]   File "/var/www/mainapp/mainapp/mainapp.wsgi", line 8, in <module>
[Sun Dec 05 17:45:00.221575 2021] [wsgi:error] [pid 21399:tid 140555088631552] [remote 192.168.1.237:53774]     exec(open(activate_this).read(), {'__file__': activate_this})
[Sun Dec 05 17:45:00.221620 2021] [wsgi:error] [pid 21399:tid 140555088631552] [remote 192.168.1.237:53774] PermissionError: [Errno 13] Permission denied: '/home/server/.local/share/virtualenvs/mainapp-c6pGQO_3/bin/activate_this.py'
[Sun Dec 05 17:45:00.284702 2021] [wsgi:error] [pid 21399:tid 140555063453440] [remote 192.168.1.237:53776] mod_wsgi (pid=21399): Target WSGI script '/var/www/mainapp/mainapp/mainapp.wsgi' cannot be loaded as Python module.
[Sun Dec 05 17:45:00.284749 2021] [wsgi:error] [pid 21399:tid 140555063453440] [remote 192.168.1.237:53776] mod_wsgi (pid=21399): Exception occurred processing WSGI script '/var/www/mainapp/mainapp/mainapp.wsgi'.
[Sun Dec 05 17:45:00.284874 2021] [wsgi:error] [pid 21399:tid 140555063453440] [remote 192.168.1.237:53776] Traceback (most recent call last):
[Sun Dec 05 17:45:00.284899 2021] [wsgi:error] [pid 21399:tid 140555063453440] [remote 192.168.1.237:53776]   File "/var/www/mainapp/mainapp/mainapp.wsgi", line 8, in <module>
[Sun Dec 05 17:45:00.284904 2021] [wsgi:error] [pid 21399:tid 140555063453440] [remote 192.168.1.237:53776]     exec(open(activate_this).read(), {'__file__': activate_this})
[Sun Dec 05 17:45:00.284920 2021] [wsgi:error] [pid 21399:tid 140555063453440] [remote 192.168.1.237:53776] PermissionError: [Errno 13] Permission denied: '/home/server/.local/share/virtualenvs/mainapp-c6pGQO_3/bin/activate_this.py'
[Mon Dec 06 13:53:56.071140 2021] [wsgi:error] [pid 32085:tid 140049443788544] [client 192.168.1.237:60058] mod_wsgi (pid=32085): Target WSGI script '/var/www/mainapp/mainapp/mainapp.wsgi' cannot be loaded as Python module.
[Mon Dec 06 13:53:56.071185 2021] [wsgi:error] [pid 32085:tid 140049443788544] [client 192.168.1.237:60058] mod_wsgi (pid=32085): Exception occurred processing WSGI script '/var/www/mainapp/mainapp/mainapp.wsgi'.
[Mon Dec 06 13:53:56.071200 2021] [wsgi:error] [pid 32085:tid 140049443788544] [client 192.168.1.237:60058] Traceback (most recent call last):
[Mon Dec 06 13:53:56.071216 2021] [wsgi:error] [pid 32085:tid 140049443788544] [client 192.168.1.237:60058]   File "/var/www/mainapp/mainapp/mainapp.wsgi", line 8, in <module>
[Mon Dec 06 13:53:56.071253 2021] [wsgi:error] [pid 32085:tid 140049443788544] [client 192.168.1.237:60058]     with open(activate_this) as file_:
[Mon Dec 06 13:53:56.071268 2021] [wsgi:error] [pid 32085:tid 140049443788544] [client 192.168.1.237:60058] IOError: [Errno 13] Permission denied: '/home/server/.local/share/virtualenvs/mainapp-c6pGQO_3/bin/activate_this.py'
[Mon Dec 06 13:57:43.838349 2021] [wsgi:error] [pid 32373:tid 140049443526400] [client 192.168.1.237:60096] mod_wsgi (pid=32373): Target WSGI script '/var/www/mainapp/mainapp/mainapp.wsgi' cannot be loaded as Python module.
[Mon Dec 06 13:57:43.838464 2021] [wsgi:error] [pid 32373:tid 140049443526400] [client 192.168.1.237:60096] mod_wsgi (pid=32373): Exception occurred processing WSGI script '/var/www/mainapp/mainapp/mainapp.wsgi'.
[Mon Dec 06 13:57:43.838519 2021] [wsgi:error] [pid 32373:tid 140049443526400] [client 192.168.1.237:60096] Traceback (most recent call last):
[Mon Dec 06 13:57:43.838572 2021] [wsgi:error] [pid 32373:tid 140049443526400] [client 192.168.1.237:60096]   File "/var/www/mainapp/mainapp/mainapp.wsgi", line 8, in <module>
[Mon Dec 06 13:57:43.838720 2021] [wsgi:error] [pid 32373:tid 140049443526400] [client 192.168.1.237:60096]     with open(activate_this) as file_:
[Mon Dec 06 13:57:43.838778 2021] [wsgi:error] [pid 32373:tid 140049443526400] [client 192.168.1.237:60096] IOError: [Errno 13] Permission denied: '/home/server/.local/share/virtualenvs/mainapp-c6pGQO_3/bin/activate_this.py'
[Mon Dec 06 13:57:44.986661 2021] [wsgi:error] [pid 32373:tid 140049354061568] [client 192.168.1.237:60098] mod_wsgi (pid=32373): Target WSGI script '/var/www/mainapp/mainapp/mainapp.wsgi' cannot be loaded as Python module.
[Mon Dec 06 13:57:44.986760 2021] [wsgi:error] [pid 32373:tid 140049354061568] [client 192.168.1.237:60098] mod_wsgi (pid=32373): Exception occurred processing WSGI script '/var/www/mainapp/mainapp/mainapp.wsgi'.
[Mon Dec 06 13:57:44.986817 2021] [wsgi:error] [pid 32373:tid 140049354061568] [client 192.168.1.237:60098] Traceback (most recent call last):
[Mon Dec 06 13:57:44.986867 2021] [wsgi:error] [pid 32373:tid 140049354061568] [client 192.168.1.237:60098]   File "/var/www/mainapp/mainapp/mainapp.wsgi", line 8, in <module>
[Mon Dec 06 13:57:44.986939 2021] [wsgi:error] [pid 32373:tid 140049354061568] [client 192.168.1.237:60098]     with open(activate_this) as file_:
[Mon Dec 06 13:57:44.986991 2021] [wsgi:error] [pid 32373:tid 140049354061568] [client 192.168.1.237:60098] IOError: [Errno 13] Permission denied: '/home/server/.local/share/virtualenvs/mainapp-c6pGQO_3/bin/activate_this.py'
[Mon Dec 06 13:59:49.784775 2021] [wsgi:error] [pid 32482:tid 140049435133696] [client 192.168.1.237:60122] mod_wsgi (pid=32482): Target WSGI script '/var/www/mainapp/mainapp/mainapp.wsgi' cannot be loaded as Python module.
[Mon Dec 06 13:59:49.784889 2021] [wsgi:error] [pid 32482:tid 140049435133696] [client 192.168.1.237:60122] mod_wsgi (pid=32482): Exception occurred processing WSGI script '/var/www/mainapp/mainapp/mainapp.wsgi'.
[Mon Dec 06 13:59:49.784944 2021] [wsgi:error] [pid 32482:tid 140049435133696] [client 192.168.1.237:60122] Traceback (most recent call last):
[Mon Dec 06 13:59:49.784999 2021] [wsgi:error] [pid 32482:tid 140049435133696] [client 192.168.1.237:60122]   File "/var/www/mainapp/mainapp/mainapp.wsgi", line 8, in <module>
[Mon Dec 06 13:59:49.785148 2021] [wsgi:error] [pid 32482:tid 140049435133696] [client 192.168.1.237:60122]     with open(activate_this) as file_:
[Mon Dec 06 13:59:49.785207 2021] [wsgi:error] [pid 32482:tid 140049435133696] [client 192.168.1.237:60122] IOError: [Errno 13] Permission denied: '/home/server/.local/share/virtualenvs/mainapp-c6pGQO_3/bin/activate_this.py'
[Mon Dec 06 14:00:02.410981 2021] [wsgi:error] [pid 32481:tid 140049435133696] [client 127.0.0.1:39036] mod_wsgi (pid=32481): Target WSGI script '/var/www/mainapp/mainapp/mainapp.wsgi' cannot be loaded as Python module.
[Mon Dec 06 14:00:02.411114 2021] [wsgi:error] [pid 32481:tid 140049435133696] [client 127.0.0.1:39036] mod_wsgi (pid=32481): Exception occurred processing WSGI script '/var/www/mainapp/mainapp/mainapp.wsgi'.
[Mon Dec 06 14:00:02.411172 2021] [wsgi:error] [pid 32481:tid 140049435133696] [client 127.0.0.1:39036] Traceback (most recent call last):
[Mon Dec 06 14:00:02.411225 2021] [wsgi:error] [pid 32481:tid 140049435133696] [client 127.0.0.1:39036]   File "/var/www/mainapp/mainapp/mainapp.wsgi", line 8, in <module>
[Mon Dec 06 14:00:02.411374 2021] [wsgi:error] [pid 32481:tid 140049435133696] [client 127.0.0.1:39036]     with open(activate_this) as file_:
[Mon Dec 06 14:00:02.411431 2021] [wsgi:error] [pid 32481:tid 140049435133696] [client 127.0.0.1:39036] IOError: [Errno 13] Permission denied: '/home/server/.local/share/virtualenvs/mainapp-c6pGQO_3/bin/activate_this.py'
[Mon Dec 06 14:00:02.491566 2021] [wsgi:error] [pid 32482:tid 140049354061568] [client 127.0.0.1:39042] mod_wsgi (pid=32482): Target WSGI script '/var/www/mainapp/mainapp/mainapp.wsgi' cannot be loaded as Python module., referer: http://localhost/
[Mon Dec 06 14:00:02.491605 2021] [wsgi:error] [pid 32482:tid 140049354061568] [client 127.0.0.1:39042] mod_wsgi (pid=32482): Exception occurred processing WSGI script '/var/www/mainapp/mainapp/mainapp.wsgi'., referer: http://localhost/
[Mon Dec 06 14:00:02.491626 2021] [wsgi:error] [pid 32482:tid 140049354061568] [client 127.0.0.1:39042] Traceback (most recent call last):, referer: http://localhost/
[Mon Dec 06 14:00:02.491644 2021] [wsgi:error] [pid 32482:tid 140049354061568] [client 127.0.0.1:39042]   File "/var/www/mainapp/mainapp/mainapp.wsgi", line 8, in <module>, referer: http://localhost/
[Mon Dec 06 14:00:02.491668 2021] [wsgi:error] [pid 32482:tid 140049354061568] [client 127.0.0.1:39042]     with open(activate_this) as file_:, referer: http://localhost/
[Mon Dec 06 14:00:02.491685 2021] [wsgi:error] [pid 32482:tid 140049354061568] [client 127.0.0.1:39042] IOError: [Errno 13] Permission denied: '/home/server/.local/share/virtualenvs/mainapp-c6pGQO_3/bin/activate_this.py', referer: http://localhost/
[Mon Dec 06 14:00:11.989175 2021] [wsgi:error] [pid 32482:tid 140049345668864] [client 192.168.1.237:60142] mod_wsgi (pid=32482): Target WSGI script '/var/www/mainapp/mainapp/mainapp.wsgi' cannot be loaded as Python module.
[Mon Dec 06 14:00:11.989277 2021] [wsgi:error] [pid 32482:tid 140049345668864] [client 192.168.1.237:60142] mod_wsgi (pid=32482): Exception occurred processing WSGI script '/var/www/mainapp/mainapp/mainapp.wsgi'.
[Mon Dec 06 14:00:11.989332 2021] [wsgi:error] [pid 32482:tid 140049345668864] [client 192.168.1.237:60142] Traceback (most recent call last):
[Mon Dec 06 14:00:11.989403 2021] [wsgi:error] [pid 32482:tid 140049345668864] [client 192.168.1.237:60142]   File "/var/www/mainapp/mainapp/mainapp.wsgi", line 8, in <module>
[Mon Dec 06 14:00:11.989474 2021] [wsgi:error] [pid 32482:tid 140049345668864] [client 192.168.1.237:60142]     with open(activate_this) as file_:
[Mon Dec 06 14:00:11.989524 2021] [wsgi:error] [pid 32482:tid 140049345668864] [client 192.168.1.237:60142] IOError: [Errno 13] Permission denied: '/home/server/.local/share/virtualenvs/mainapp-c6pGQO_3/bin/activate_this.py'
[Mon Dec 06 14:00:12.040664 2021] [wsgi:error] [pid 32482:tid 140049328883456] [client 192.168.1.237:60144] mod_wsgi (pid=32482): Target WSGI script '/var/www/mainapp/mainapp/mainapp.wsgi' cannot be loaded as Python module., referer: http://192.168.1.237/
[Mon Dec 06 14:00:12.040698 2021] [wsgi:error] [pid 32482:tid 140049328883456] [client 192.168.1.237:60144] mod_wsgi (pid=32482): Exception occurred processing WSGI script '/var/www/mainapp/mainapp/mainapp.wsgi'., referer: http://192.168.1.237/
[Mon Dec 06 14:00:12.040716 2021] [wsgi:error] [pid 32482:tid 140049328883456] [client 192.168.1.237:60144] Traceback (most recent call last):, referer: http://192.168.1.237/
[Mon Dec 06 14:00:12.040735 2021] [wsgi:error] [pid 32482:tid 140049328883456] [client 192.168.1.237:60144]   File "/var/www/mainapp/mainapp/mainapp.wsgi", line 8, in <module>, referer: http://192.168.1.237/
[Mon Dec 06 14:00:12.040759 2021] [wsgi:error] [pid 32482:tid 140049328883456] [client 192.168.1.237:60144]     with open(activate_this) as file_:, referer: http://192.168.1.237/
[Mon Dec 06 14:00:12.040776 2021] [wsgi:error] [pid 32482:tid 140049328883456] [client 192.168.1.237:60144] IOError: [Errno 13] Permission denied: '/home/server/.local/share/virtualenvs/mainapp-c6pGQO_3/bin/activate_this.py', referer: http://192.168.1.237/
[Mon Dec 06 14:00:21.172248 2021] [wsgi:error] [pid 32482:tid 140049443526400] [client 192.168.1.237:60150] mod_wsgi (pid=32482): Target WSGI script '/var/www/mainapp/mainapp/mainapp.wsgi' cannot be loaded as Python module.
[Mon Dec 06 14:00:21.172282 2021] [wsgi:error] [pid 32482:tid 140049443526400] [client 192.168.1.237:60150] mod_wsgi (pid=32482): Exception occurred processing WSGI script '/var/www/mainapp/mainapp/mainapp.wsgi'.
[Mon Dec 06 14:00:21.172297 2021] [wsgi:error] [pid 32482:tid 140049443526400] [client 192.168.1.237:60150] Traceback (most recent call last):
[Mon Dec 06 14:00:21.172312 2021] [wsgi:error] [pid 32482:tid 140049443526400] [client 192.168.1.237:60150]   File "/var/www/mainapp/mainapp/mainapp.wsgi", line 8, in <module>
[Mon Dec 06 14:00:21.172333 2021] [wsgi:error] [pid 32482:tid 140049443526400] [client 192.168.1.237:60150]     with open(activate_this) as file_:
[Mon Dec 06 14:00:21.172347 2021] [wsgi:error] [pid 32482:tid 140049443526400] [client 192.168.1.237:60150] IOError: [Errno 13] Permission denied: '/home/server/.local/share/virtualenvs/mainapp-c6pGQO_3/bin/activate_this.py'
[Mon Dec 06 14:00:21.204182 2021] [wsgi:error] [pid 32482:tid 140049337276160] [client 192.168.1.237:60152] mod_wsgi (pid=32482): Target WSGI script '/var/www/mainapp/mainapp/mainapp.wsgi' cannot be loaded as Python module., referer: http://192.168.1.237/
[Mon Dec 06 14:00:21.204359 2021] [wsgi:error] [pid 32482:tid 140049337276160] [client 192.168.1.237:60152] mod_wsgi (pid=32482): Exception occurred processing WSGI script '/var/www/mainapp/mainapp/mainapp.wsgi'., referer: http://192.168.1.237/
[Mon Dec 06 14:00:21.204409 2021] [wsgi:error] [pid 32482:tid 140049337276160] [client 192.168.1.237:60152] Traceback (most recent call last):, referer: http://192.168.1.237/
[Mon Dec 06 14:00:21.204471 2021] [wsgi:error] [pid 32482:tid 140049337276160] [client 192.168.1.237:60152]   File "/var/www/mainapp/mainapp/mainapp.wsgi", line 8, in <module>, referer: http://192.168.1.237/
[Mon Dec 06 14:00:21.204523 2021] [wsgi:error] [pid 32482:tid 140049337276160] [client 192.168.1.237:60152]     with open(activate_this) as file_:, referer: http://192.168.1.237/
[Mon Dec 06 14:00:21.204561 2021] [wsgi:error] [pid 32482:tid 140049337276160] [client 192.168.1.237:60152] IOError: [Errno 13] Permission denied: '/home/server/.local/share/virtualenvs/mainapp-c6pGQO_3/bin/activate_this.py', referer: http://192.168.1.237/
[Mon Dec 06 14:02:33.125583 2021] [wsgi:error] [pid 32673:tid 140049443526400] [client 192.168.1.237:60170] mod_wsgi (pid=32673): Target WSGI script '/var/www/mainapp/mainapp/mainapp.wsgi' cannot be loaded as Python module.
[Mon Dec 06 14:02:33.125709 2021] [wsgi:error] [pid 32673:tid 140049443526400] [client 192.168.1.237:60170] mod_wsgi (pid=32673): Exception occurred processing WSGI script '/var/www/mainapp/mainapp/mainapp.wsgi'.
[Mon Dec 06 14:02:33.125765 2021] [wsgi:error] [pid 32673:tid 140049443526400] [client 192.168.1.237:60170] Traceback (most recent call last):
[Mon Dec 06 14:02:33.125818 2021] [wsgi:error] [pid 32673:tid 140049443526400] [client 192.168.1.237:60170]   File "/var/www/mainapp/mainapp/mainapp.wsgi", line 8, in <module>
[Mon Dec 06 14:02:33.125966 2021] [wsgi:error] [pid 32673:tid 140049443526400] [client 192.168.1.237:60170]     with open(activate_this) as file_:
[Mon Dec 06 14:02:33.126025 2021] [wsgi:error] [pid 32673:tid 140049443526400] [client 192.168.1.237:60170] IOError: [Errno 13] Permission denied: '/home/server/.local/share/virtualenvs/mainapp-c6pGQO_3/bin/activate_this.py'
[Mon Dec 06 14:02:34.353704 2021] [wsgi:error] [pid 32673:tid 140049354061568] [client 192.168.1.237:60172] mod_wsgi (pid=32673): Target WSGI script '/var/www/mainapp/mainapp/mainapp.wsgi' cannot be loaded as Python module.
[Mon Dec 06 14:02:34.353844 2021] [wsgi:error] [pid 32673:tid 140049354061568] [client 192.168.1.237:60172] mod_wsgi (pid=32673): Exception occurred processing WSGI script '/var/www/mainapp/mainapp/mainapp.wsgi'.
[Mon Dec 06 14:02:34.353911 2021] [wsgi:error] [pid 32673:tid 140049354061568] [client 192.168.1.237:60172] Traceback (most recent call last):
[Mon Dec 06 14:02:34.353973 2021] [wsgi:error] [pid 32673:tid 140049354061568] [client 192.168.1.237:60172]   File "/var/www/mainapp/mainapp/mainapp.wsgi", line 8, in <module>
[Mon Dec 06 14:02:34.354065 2021] [wsgi:error] [pid 32673:tid 140049354061568] [client 192.168.1.237:60172]     with open(activate_this) as file_:
[Mon Dec 06 14:02:34.354126 2021] [wsgi:error] [pid 32673:tid 140049354061568] [client 192.168.1.237:60172] IOError: [Errno 13] Permission denied: '/home/server/.local/share/virtualenvs/mainapp-c6pGQO_3/bin/activate_this.py'
[Mon Dec 06 14:04:31.091113 2021] [wsgi:error] [pid 307:tid 140049345668864] [client 192.168.1.237:60198] mod_wsgi (pid=307): Target WSGI script '/var/www/mainapp/mainapp/mainapp.wsgi' cannot be loaded as Python module.
[Mon Dec 06 14:04:31.091241 2021] [wsgi:error] [pid 307:tid 140049345668864] [client 192.168.1.237:60198] mod_wsgi (pid=307): Exception occurred processing WSGI script '/var/www/mainapp/mainapp/mainapp.wsgi'.
[Mon Dec 06 14:04:31.091295 2021] [wsgi:error] [pid 307:tid 140049345668864] [client 192.168.1.237:60198] Traceback (most recent call last):
[Mon Dec 06 14:04:31.091366 2021] [wsgi:error] [pid 307:tid 140049345668864] [client 192.168.1.237:60198]   File "/var/www/mainapp/mainapp/mainapp.wsgi", line 8, in <module>
[Mon Dec 06 14:04:31.091517 2021] [wsgi:error] [pid 307:tid 140049345668864] [client 192.168.1.237:60198]     with open(activate_this) as file_:
[Mon Dec 06 14:04:31.091577 2021] [wsgi:error] [pid 307:tid 140049345668864] [client 192.168.1.237:60198] IOError: [Errno 13] Permission denied: '/home/server/.local/share/virtualenvs/mainapp-c6pGQO_3/bin/activate_this.py'
[Mon Dec 06 14:04:32.675666 2021] [wsgi:error] [pid 307:tid 140049337276160] [client 192.168.1.237:60200] mod_wsgi (pid=307): Target WSGI script '/var/www/mainapp/mainapp/mainapp.wsgi' cannot be loaded as Python module.
[Mon Dec 06 14:04:32.675702 2021] [wsgi:error] [pid 307:tid 140049337276160] [client 192.168.1.237:60200] mod_wsgi (pid=307): Exception occurred processing WSGI script '/var/www/mainapp/mainapp/mainapp.wsgi'.
[Mon Dec 06 14:04:32.675717 2021] [wsgi:error] [pid 307:tid 140049337276160] [client 192.168.1.237:60200] Traceback (most recent call last):
[Mon Dec 06 14:04:32.675738 2021] [wsgi:error] [pid 307:tid 140049337276160] [client 192.168.1.237:60200]   File "/var/www/mainapp/mainapp/mainapp.wsgi", line 8, in <module>
[Mon Dec 06 14:04:32.675757 2021] [wsgi:error] [pid 307:tid 140049337276160] [client 192.168.1.237:60200]     with open(activate_this) as file_:
[Mon Dec 06 14:04:32.675770 2021] [wsgi:error] [pid 307:tid 140049337276160] [client 192.168.1.237:60200] IOError: [Errno 13] Permission denied: '/home/server/.local/share/virtualenvs/mainapp-c6pGQO_3/bin/activate_this.py'
[Mon Dec 06 14:06:54.936147 2021] [wsgi:error] [pid 307:tid 140049328883456] [client 192.168.1.237:60258] mod_wsgi (pid=307): Target WSGI script '/var/www/mainapp/mainapp/mainapp.wsgi' cannot be loaded as Python module.
[Mon Dec 06 14:06:54.936281 2021] [wsgi:error] [pid 307:tid 140049328883456] [client 192.168.1.237:60258] mod_wsgi (pid=307): Exception occurred processing WSGI script '/var/www/mainapp/mainapp/mainapp.wsgi'.
[Mon Dec 06 14:06:54.936342 2021] [wsgi:error] [pid 307:tid 140049328883456] [client 192.168.1.237:60258] Traceback (most recent call last):
[Mon Dec 06 14:06:54.936393 2021] [wsgi:error] [pid 307:tid 140049328883456] [client 192.168.1.237:60258]   File "/var/www/mainapp/mainapp/mainapp.wsgi", line 8, in <module>
[Mon Dec 06 14:06:54.936487 2021] [wsgi:error] [pid 307:tid 140049328883456] [client 192.168.1.237:60258]     with open(activate_this) as file_:
[Mon Dec 06 14:06:54.936550 2021] [wsgi:error] [pid 307:tid 140049328883456] [client 192.168.1.237:60258] IOError: [Errno 13] Permission denied: '/home/server/.local/share/virtualenvs/mainapp-c6pGQO_3/bin/activate_this.py'
[Mon Dec 06 14:22:48.469940 2021] [wsgi:error] [pid 904:tid 140330204657408] [client 192.168.1.237:60748] mod_wsgi (pid=904): Target WSGI script '/var/www/mainapp/mainapp/mainapp.wsgi' cannot be loaded as Python module.
[Mon Dec 06 14:22:48.470002 2021] [wsgi:error] [pid 904:tid 140330204657408] [client 192.168.1.237:60748] mod_wsgi (pid=904): Exception occurred processing WSGI script '/var/www/mainapp/mainapp/mainapp.wsgi'.
[Mon Dec 06 14:22:48.470019 2021] [wsgi:error] [pid 904:tid 140330204657408] [client 192.168.1.237:60748] Traceback (most recent call last):
[Mon Dec 06 14:22:48.470037 2021] [wsgi:error] [pid 904:tid 140330204657408] [client 192.168.1.237:60748]   File "/var/www/mainapp/mainapp/mainapp.wsgi", line 8, in <module>
[Mon Dec 06 14:22:48.470081 2021] [wsgi:error] [pid 904:tid 140330204657408] [client 192.168.1.237:60748]     with open(activate_this) as file_:
[Mon Dec 06 14:22:48.470098 2021] [wsgi:error] [pid 904:tid 140330204657408] [client 192.168.1.237:60748] IOError: [Errno 13] Permission denied: '/home/server/.local/share/virtualenvs/mainapp-c6pGQO_3/bin/activate_this.py'
[Mon Dec 06 14:22:49.862060 2021] [wsgi:error] [pid 905:tid 140330204657408] [client 192.168.1.237:60754] mod_wsgi (pid=905): Target WSGI script '/var/www/mainapp/mainapp/mainapp.wsgi' cannot be loaded as Python module.
[Mon Dec 06 14:22:49.862118 2021] [wsgi:error] [pid 905:tid 140330204657408] [client 192.168.1.237:60754] mod_wsgi (pid=905): Exception occurred processing WSGI script '/var/www/mainapp/mainapp/mainapp.wsgi'.
[Mon Dec 06 14:22:49.862137 2021] [wsgi:error] [pid 905:tid 140330204657408] [client 192.168.1.237:60754] Traceback (most recent call last):
[Mon Dec 06 14:22:49.862158 2021] [wsgi:error] [pid 905:tid 140330204657408] [client 192.168.1.237:60754]   File "/var/www/mainapp/mainapp/mainapp.wsgi", line 8, in <module>
[Mon Dec 06 14:22:49.862204 2021] [wsgi:error] [pid 905:tid 140330204657408] [client 192.168.1.237:60754]     with open(activate_this) as file_:
[Mon Dec 06 14:22:49.862222 2021] [wsgi:error] [pid 905:tid 140330204657408] [client 192.168.1.237:60754] IOError: [Errno 13] Permission denied: '/home/server/.local/share/virtualenvs/mainapp-c6pGQO_3/bin/activate_this.py'
[Mon Dec 06 14:22:51.971610 2021] [wsgi:error] [pid 905:tid 140330196264704] [client 192.168.1.237:60756] mod_wsgi (pid=905): Target WSGI script '/var/www/mainapp/mainapp/mainapp.wsgi' cannot be loaded as Python module.
[Mon Dec 06 14:22:51.971650 2021] [wsgi:error] [pid 905:tid 140330196264704] [client 192.168.1.237:60756] mod_wsgi (pid=905): Exception occurred processing WSGI script '/var/www/mainapp/mainapp/mainapp.wsgi'.
[Mon Dec 06 14:22:51.971670 2021] [wsgi:error] [pid 905:tid 140330196264704] [client 192.168.1.237:60756] Traceback (most recent call last):
[Mon Dec 06 14:22:51.971688 2021] [wsgi:error] [pid 905:tid 140330196264704] [client 192.168.1.237:60756]   File "/var/www/mainapp/mainapp/mainapp.wsgi", line 8, in <module>
[Mon Dec 06 14:22:51.971712 2021] [wsgi:error] [pid 905:tid 140330196264704] [client 192.168.1.237:60756]     with open(activate_this) as file_:
[Mon Dec 06 14:22:51.971730 2021] [wsgi:error] [pid 905:tid 140330196264704] [client 192.168.1.237:60756] IOError: [Errno 13] Permission denied: '/home/server/.local/share/virtualenvs/mainapp-c6pGQO_3/bin/activate_this.py'
[Mon Dec 06 14:22:54.220570 2021] [wsgi:error] [pid 905:tid 140330070439680] [client 192.168.1.237:60758] mod_wsgi (pid=905): Target WSGI script '/var/www/mainapp/mainapp/mainapp.wsgi' cannot be loaded as Python module.
[Mon Dec 06 14:22:54.220674 2021] [wsgi:error] [pid 905:tid 140330070439680] [client 192.168.1.237:60758] mod_wsgi (pid=905): Exception occurred processing WSGI script '/var/www/mainapp/mainapp/mainapp.wsgi'.
[Mon Dec 06 14:22:54.220731 2021] [wsgi:error] [pid 905:tid 140330070439680] [client 192.168.1.237:60758] Traceback (most recent call last):
[Mon Dec 06 14:22:54.220782 2021] [wsgi:error] [pid 905:tid 140330070439680] [client 192.168.1.237:60758]   File "/var/www/mainapp/mainapp/mainapp.wsgi", line 8, in <module>
[Mon Dec 06 14:22:54.220855 2021] [wsgi:error] [pid 905:tid 140330070439680] [client 192.168.1.237:60758]     with open(activate_this) as file_:
[Mon Dec 06 14:22:54.220905 2021] [wsgi:error] [pid 905:tid 140330070439680] [client 192.168.1.237:60758] IOError: [Errno 13] Permission denied: '/home/server/.local/share/virtualenvs/mainapp-c6pGQO_3/bin/activate_this.py'
[Mon Dec 06 14:38:03.129339 2021] [wsgi:error] [pid 905:tid 140330187872000] [client 192.168.1.7:58668] mod_wsgi (pid=905): Target WSGI script '/var/www/mainapp/mainapp/mainapp.wsgi' cannot be loaded as Python module.
[Mon Dec 06 14:38:03.129448 2021] [wsgi:error] [pid 905:tid 140330187872000] [client 192.168.1.7:58668] mod_wsgi (pid=905): Exception occurred processing WSGI script '/var/www/mainapp/mainapp/mainapp.wsgi'.
[Mon Dec 06 14:38:03.129503 2021] [wsgi:error] [pid 905:tid 140330187872000] [client 192.168.1.7:58668] Traceback (most recent call last):
[Mon Dec 06 14:38:03.129555 2021] [wsgi:error] [pid 905:tid 140330187872000] [client 192.168.1.7:58668]   File "/var/www/mainapp/mainapp/mainapp.wsgi", line 8, in <module>
[Mon Dec 06 14:38:03.129628 2021] [wsgi:error] [pid 905:tid 140330187872000] [client 192.168.1.7:58668]     with open(activate_this) as file_:
[Mon Dec 06 14:38:03.129679 2021] [wsgi:error] [pid 905:tid 140330187872000] [client 192.168.1.7:58668] IOError: [Errno 13] Permission denied: '/home/server/.local/share/virtualenvs/mainapp-c6pGQO_3/bin/activate_this.py'
[Mon Dec 06 14:38:03.339855 2021] [wsgi:error] [pid 905:tid 140330154301184] [client 192.168.1.7:58670] mod_wsgi (pid=905): Target WSGI script '/var/www/mainapp/mainapp/mainapp.wsgi' cannot be loaded as Python module., referer: http://192.168.1.237/
[Mon Dec 06 14:38:03.339950 2021] [wsgi:error] [pid 905:tid 140330154301184] [client 192.168.1.7:58670] mod_wsgi (pid=905): Exception occurred processing WSGI script '/var/www/mainapp/mainapp/mainapp.wsgi'., referer: http://192.168.1.237/
[Mon Dec 06 14:38:03.340004 2021] [wsgi:error] [pid 905:tid 140330154301184] [client 192.168.1.7:58670] Traceback (most recent call last):, referer: http://192.168.1.237/
[Mon Dec 06 14:38:03.340062 2021] [wsgi:error] [pid 905:tid 140330154301184] [client 192.168.1.7:58670]   File "/var/www/mainapp/mainapp/mainapp.wsgi", line 8, in <module>, referer: http://192.168.1.237/
[Mon Dec 06 14:38:03.340130 2021] [wsgi:error] [pid 905:tid 140330154301184] [client 192.168.1.7:58670]     with open(activate_this) as file_:, referer: http://192.168.1.237/
[Mon Dec 06 14:38:03.340201 2021] [wsgi:error] [pid 905:tid 140330154301184] [client 192.168.1.7:58670] IOError: [Errno 13] Permission denied: '/home/server/.local/share/virtualenvs/mainapp-c6pGQO_3/bin/activate_this.py', referer: http://192.168.1.237/
[Mon Dec 06 14:38:13.908505 2021] [wsgi:error] [pid 905:tid 140330062046976] [client 192.168.1.7:58674] mod_wsgi (pid=905): Target WSGI script '/var/www/mainapp/mainapp/mainapp.wsgi' cannot be loaded as Python module.
[Mon Dec 06 14:38:13.908612 2021] [wsgi:error] [pid 905:tid 140330062046976] [client 192.168.1.7:58674] mod_wsgi (pid=905): Exception occurred processing WSGI script '/var/www/mainapp/mainapp/mainapp.wsgi'.
[Mon Dec 06 14:38:13.908664 2021] [wsgi:error] [pid 905:tid 140330062046976] [client 192.168.1.7:58674] Traceback (most recent call last):
[Mon Dec 06 14:38:13.908713 2021] [wsgi:error] [pid 905:tid 140330062046976] [client 192.168.1.7:58674]   File "/var/www/mainapp/mainapp/mainapp.wsgi", line 8, in <module>
[Mon Dec 06 14:38:13.908782 2021] [wsgi:error] [pid 905:tid 140330062046976] [client 192.168.1.7:58674]     with open(activate_this) as file_:
[Mon Dec 06 14:38:13.908832 2021] [wsgi:error] [pid 905:tid 140330062046976] [client 192.168.1.7:58674] IOError: [Errno 13] Permission denied: '/home/server/.local/share/virtualenvs/mainapp-c6pGQO_3/bin/activate_this.py'
[Mon Dec 06 17:01:00.563788 2021] [wsgi:error] [pid 904:tid 140330196264704] [client 192.168.1.237:33716] mod_wsgi (pid=904): Target WSGI script '/var/www/mainapp/mainapp/mainapp.wsgi' cannot be loaded as Python module.
[Mon Dec 06 17:01:00.563875 2021] [wsgi:error] [pid 904:tid 140330196264704] [client 192.168.1.237:33716] mod_wsgi (pid=904): Exception occurred processing WSGI script '/var/www/mainapp/mainapp/mainapp.wsgi'.
[Mon Dec 06 17:01:00.563920 2021] [wsgi:error] [pid 904:tid 140330196264704] [client 192.168.1.237:33716] Traceback (most recent call last):
[Mon Dec 06 17:01:00.563968 2021] [wsgi:error] [pid 904:tid 140330196264704] [client 192.168.1.237:33716]   File "/var/www/mainapp/mainapp/mainapp.wsgi", line 8, in <module>
[Mon Dec 06 17:01:00.564026 2021] [wsgi:error] [pid 904:tid 140330196264704] [client 192.168.1.237:33716]     with open(activate_this) as file_:
[Mon Dec 06 17:01:00.564068 2021] [wsgi:error] [pid 904:tid 140330196264704] [client 192.168.1.237:33716] IOError: [Errno 13] Permission denied: '/home/server/.local/share/virtualenvs/mainapp-c6pGQO_3/bin/activate_this.py'
[Mon Dec 06 17:17:40.853425 2021] [wsgi:error] [pid 2899:tid 140645898790656] [client 192.168.1.237:33850] mod_wsgi (pid=2899): Target WSGI script '/var/www/mainapp/mainapp/mainapp.wsgi' cannot be loaded as Python module.
[Mon Dec 06 17:17:40.853550 2021] [wsgi:error] [pid 2899:tid 140645898790656] [client 192.168.1.237:33850] mod_wsgi (pid=2899): Exception occurred processing WSGI script '/var/www/mainapp/mainapp/mainapp.wsgi'.
[Mon Dec 06 17:17:40.853596 2021] [wsgi:error] [pid 2899:tid 140645898790656] [client 192.168.1.237:33850] Traceback (most recent call last):
[Mon Dec 06 17:17:40.853639 2021] [wsgi:error] [pid 2899:tid 140645898790656] [client 192.168.1.237:33850]   File "/var/www/mainapp/mainapp/mainapp.wsgi", line 8, in <module>
[Mon Dec 06 17:17:40.853759 2021] [wsgi:error] [pid 2899:tid 140645898790656] [client 192.168.1.237:33850]     with open(activate_this) as file_:
[Mon Dec 06 17:17:40.853805 2021] [wsgi:error] [pid 2899:tid 140645898790656] [client 192.168.1.237:33850] IOError: [Errno 13] Permission denied: '/home/server/.local/share/virtualenvs/mainapp-c6pGQO_3/bin/activate_this.py'
[Mon Dec 06 17:17:44.032174 2021] [wsgi:error] [pid 2899:tid 140645817644800] [client 192.168.1.237:33852] mod_wsgi (pid=2899): Target WSGI script '/var/www/mainapp/mainapp/mainapp.wsgi' cannot be loaded as Python module.
[Mon Dec 06 17:17:44.032312 2021] [wsgi:error] [pid 2899:tid 140645817644800] [client 192.168.1.237:33852] mod_wsgi (pid=2899): Exception occurred processing WSGI script '/var/www/mainapp/mainapp/mainapp.wsgi'.
[Mon Dec 06 17:17:44.032396 2021] [wsgi:error] [pid 2899:tid 140645817644800] [client 192.168.1.237:33852] Traceback (most recent call last):
[Mon Dec 06 17:17:44.032448 2021] [wsgi:error] [pid 2899:tid 140645817644800] [client 192.168.1.237:33852]   File "/var/www/mainapp/mainapp/mainapp.wsgi", line 8, in <module>
[Mon Dec 06 17:17:44.032522 2021] [wsgi:error] [pid 2899:tid 140645817644800] [client 192.168.1.237:33852]     with open(activate_this) as file_:
[Mon Dec 06 17:17:44.032573 2021] [wsgi:error] [pid 2899:tid 140645817644800] [client 192.168.1.237:33852] IOError: [Errno 13] Permission denied: '/home/server/.local/share/virtualenvs/mainapp-c6pGQO_3/bin/activate_this.py'
[Mon Dec 06 17:17:53.913705 2021] [wsgi:error] [pid 2899:tid 140645800859392] [client 192.168.1.237:33854] mod_wsgi (pid=2899): Target WSGI script '/var/www/mainapp/mainapp/mainapp.wsgi' cannot be loaded as Python module.
[Mon Dec 06 17:17:53.913746 2021] [wsgi:error] [pid 2899:tid 140645800859392] [client 192.168.1.237:33854] mod_wsgi (pid=2899): Exception occurred processing WSGI script '/var/www/mainapp/mainapp/mainapp.wsgi'.
[Mon Dec 06 17:17:53.913767 2021] [wsgi:error] [pid 2899:tid 140645800859392] [client 192.168.1.237:33854] Traceback (most recent call last):
[Mon Dec 06 17:17:53.913787 2021] [wsgi:error] [pid 2899:tid 140645800859392] [client 192.168.1.237:33854]   File "/var/www/mainapp/mainapp/mainapp.wsgi", line 8, in <module>
[Mon Dec 06 17:17:53.913818 2021] [wsgi:error] [pid 2899:tid 140645800859392] [client 192.168.1.237:33854]     with open(activate_this) as file_:
[Mon Dec 06 17:17:53.913838 2021] [wsgi:error] [pid 2899:tid 140645800859392] [client 192.168.1.237:33854] IOError: [Errno 13] Permission denied: '/home/server/.local/share/virtualenvs/mainapp-c6pGQO_3/bin/activate_this.py'
[Mon Dec 06 17:17:55.052656 2021] [wsgi:error] [pid 2899:tid 140645809252096] [client 192.168.1.237:33856] mod_wsgi (pid=2899): Target WSGI script '/var/www/mainapp/mainapp/mainapp.wsgi' cannot be loaded as Python module.
[Mon Dec 06 17:17:55.052758 2021] [wsgi:error] [pid 2899:tid 140645809252096] [client 192.168.1.237:33856] mod_wsgi (pid=2899): Exception occurred processing WSGI script '/var/www/mainapp/mainapp/mainapp.wsgi'.
[Mon Dec 06 17:17:55.052812 2021] [wsgi:error] [pid 2899:tid 140645809252096] [client 192.168.1.237:33856] Traceback (most recent call last):
[Mon Dec 06 17:17:55.052863 2021] [wsgi:error] [pid 2899:tid 140645809252096] [client 192.168.1.237:33856]   File "/var/www/mainapp/mainapp/mainapp.wsgi", line 8, in <module>
[Mon Dec 06 17:17:55.052936 2021] [wsgi:error] [pid 2899:tid 140645809252096] [client 192.168.1.237:33856]     with open(activate_this) as file_:
[Mon Dec 06 17:17:55.052987 2021] [wsgi:error] [pid 2899:tid 140645809252096] [client 192.168.1.237:33856] IOError: [Errno 13] Permission denied: '/home/server/.local/share/virtualenvs/mainapp-c6pGQO_3/bin/activate_this.py'
[Mon Dec 06 17:18:13.260514 2021] [wsgi:error] [pid 2899:tid 140645792466688] [client 192.168.1.237:33862] mod_wsgi (pid=2899): Target WSGI script '/var/www/mainapp/mainapp/mainapp.wsgi' cannot be loaded as Python module.
[Mon Dec 06 17:18:13.260617 2021] [wsgi:error] [pid 2899:tid 140645792466688] [client 192.168.1.237:33862] mod_wsgi (pid=2899): Exception occurred processing WSGI script '/var/www/mainapp/mainapp/mainapp.wsgi'.
[Mon Dec 06 17:18:13.260777 2021] [wsgi:error] [pid 2899:tid 140645792466688] [client 192.168.1.237:33862] Traceback (most recent call last):
[Mon Dec 06 17:18:13.260846 2021] [wsgi:error] [pid 2899:tid 140645792466688] [client 192.168.1.237:33862]   File "/var/www/mainapp/mainapp/mainapp.wsgi", line 8, in <module>
[Mon Dec 06 17:18:13.260936 2021] [wsgi:error] [pid 2899:tid 140645792466688] [client 192.168.1.237:33862]     with open(activate_this) as file_:
[Mon Dec 06 17:18:13.260991 2021] [wsgi:error] [pid 2899:tid 140645792466688] [client 192.168.1.237:33862] IOError: [Errno 13] Permission denied: '/home/server/.local/share/virtualenvs/mainapp-c6pGQO_3/bin/activate_this.py'
[Mon Dec 06 17:29:27.009778 2021] [wsgi:error] [pid 3215:tid 140503761520384] [client 192.168.1.237:33964] mod_wsgi (pid=3215): Target WSGI script '/var/www/mainapp/mainapp/mainapp.wsgi' cannot be loaded as Python module.
[Mon Dec 06 17:29:27.009916 2021] [wsgi:error] [pid 3215:tid 140503761520384] [client 192.168.1.237:33964] mod_wsgi (pid=3215): Exception occurred processing WSGI script '/var/www/mainapp/mainapp/mainapp.wsgi'.
[Mon Dec 06 17:29:27.009981 2021] [wsgi:error] [pid 3215:tid 140503761520384] [client 192.168.1.237:33964] Traceback (most recent call last):
[Mon Dec 06 17:29:27.010037 2021] [wsgi:error] [pid 3215:tid 140503761520384] [client 192.168.1.237:33964]   File "/var/www/mainapp/mainapp/mainapp.wsgi", line 8, in <module>
[Mon Dec 06 17:29:27.010242 2021] [wsgi:error] [pid 3215:tid 140503761520384] [client 192.168.1.237:33964]     with open(activate_this) as file_:
[Mon Dec 06 17:29:27.010306 2021] [wsgi:error] [pid 3215:tid 140503761520384] [client 192.168.1.237:33964] IOError: [Errno 13] Permission denied: '/home/server/.local/share/virtualenvs/mainapp-c6pGQO_3/bin/activate_this.py'
[Mon Dec 06 17:29:30.458418 2021] [wsgi:error] [pid 3216:tid 140503681070848] [client 192.168.1.237:33966] mod_wsgi (pid=3216): Target WSGI script '/var/www/mainapp/mainapp/mainapp.wsgi' cannot be loaded as Python module.
[Mon Dec 06 17:29:30.458541 2021] [wsgi:error] [pid 3216:tid 140503681070848] [client 192.168.1.237:33966] mod_wsgi (pid=3216): Exception occurred processing WSGI script '/var/www/mainapp/mainapp/mainapp.wsgi'.
[Mon Dec 06 17:29:30.458597 2021] [wsgi:error] [pid 3216:tid 140503681070848] [client 192.168.1.237:33966] Traceback (most recent call last):
[Mon Dec 06 17:29:30.458651 2021] [wsgi:error] [pid 3216:tid 140503681070848] [client 192.168.1.237:33966]   File "/var/www/mainapp/mainapp/mainapp.wsgi", line 8, in <module>
[Mon Dec 06 17:29:30.458798 2021] [wsgi:error] [pid 3216:tid 140503681070848] [client 192.168.1.237:33966]     with open(activate_this) as file_:
[Mon Dec 06 17:29:30.458858 2021] [wsgi:error] [pid 3216:tid 140503681070848] [client 192.168.1.237:33966] IOError: [Errno 13] Permission denied: '/home/server/.local/share/virtualenvs/mainapp-c6pGQO_3/bin/activate_this.py'
[Mon Dec 06 17:50:05.562408 2021] [wsgi:error] [pid 3470:tid 140503761520384] [client 192.168.1.237:34112] mod_wsgi (pid=3470): Target WSGI script '/var/www/mainapp/mainapp/mainapp.wsgi' cannot be loaded as Python module.
[Mon Dec 06 17:50:05.562595 2021] [wsgi:error] [pid 3470:tid 140503761520384] [client 192.168.1.237:34112] mod_wsgi (pid=3470): Exception occurred processing WSGI script '/var/www/mainapp/mainapp/mainapp.wsgi'.
[Mon Dec 06 17:50:05.562682 2021] [wsgi:error] [pid 3470:tid 140503761520384] [client 192.168.1.237:34112] Traceback (most recent call last):
[Mon Dec 06 17:50:05.562763 2021] [wsgi:error] [pid 3470:tid 140503761520384] [client 192.168.1.237:34112]   File "/var/www/mainapp/mainapp/mainapp.wsgi", line 8, in <module>
[Mon Dec 06 17:50:05.562995 2021] [wsgi:error] [pid 3470:tid 140503761520384] [client 192.168.1.237:34112]     with open(activate_this) as file_:
[Mon Dec 06 17:50:05.563092 2021] [wsgi:error] [pid 3470:tid 140503761520384] [client 192.168.1.237:34112] IOError: [Errno 13] Permission denied: '/home/server/.local/share/virtualenvs/mainapp-c6pGQO_3/bin/activate_this.py'
[Mon Dec 06 17:50:08.636645 2021] [wsgi:error] [pid 3470:tid 140503681070848] [client 192.168.1.237:34114] mod_wsgi (pid=3470): Target WSGI script '/var/www/mainapp/mainapp/mainapp.wsgi' cannot be loaded as Python module.
[Mon Dec 06 17:50:08.636749 2021] [wsgi:error] [pid 3470:tid 140503681070848] [client 192.168.1.237:34114] mod_wsgi (pid=3470): Exception occurred processing WSGI script '/var/www/mainapp/mainapp/mainapp.wsgi'.
[Mon Dec 06 17:50:08.636809 2021] [wsgi:error] [pid 3470:tid 140503681070848] [client 192.168.1.237:34114] Traceback (most recent call last):
[Mon Dec 06 17:50:08.636859 2021] [wsgi:error] [pid 3470:tid 140503681070848] [client 192.168.1.237:34114]   File "/var/www/mainapp/mainapp/mainapp.wsgi", line 8, in <module>
[Mon Dec 06 17:50:08.636952 2021] [wsgi:error] [pid 3470:tid 140503681070848] [client 192.168.1.237:34114]     with open(activate_this) as file_:
[Mon Dec 06 17:50:08.637008 2021] [wsgi:error] [pid 3470:tid 140503681070848] [client 192.168.1.237:34114] IOError: [Errno 13] Permission denied: '/home/server/.local/share/virtualenvs/mainapp-c6pGQO_3/bin/activate_this.py'
[Mon Dec 06 17:50:46.936710 2021] [wsgi:error] [pid 3470:tid 140503672678144] [client 192.168.1.237:34120] mod_wsgi (pid=3470): Target WSGI script '/var/www/mainapp/mainapp/mainapp.wsgi' cannot be loaded as Python module.
[Mon Dec 06 17:50:46.936823 2021] [wsgi:error] [pid 3470:tid 140503672678144] [client 192.168.1.237:34120] mod_wsgi (pid=3470): Exception occurred processing WSGI script '/var/www/mainapp/mainapp/mainapp.wsgi'.
[Mon Dec 06 17:50:46.936895 2021] [wsgi:error] [pid 3470:tid 140503672678144] [client 192.168.1.237:34120] Traceback (most recent call last):
[Mon Dec 06 17:50:46.936946 2021] [wsgi:error] [pid 3470:tid 140503672678144] [client 192.168.1.237:34120]   File "/var/www/mainapp/mainapp/mainapp.wsgi", line 8, in <module>
[Mon Dec 06 17:50:46.937035 2021] [wsgi:error] [pid 3470:tid 140503672678144] [client 192.168.1.237:34120]     with open(activate_this) as file_:
[Mon Dec 06 17:50:46.937096 2021] [wsgi:error] [pid 3470:tid 140503672678144] [client 192.168.1.237:34120] IOError: [Errno 13] Permission denied: '/home/server/.local/share/virtualenvs/mainapp-c6pGQO_3/bin/activate_this.py'
[Mon Dec 06 17:50:50.425644 2021] [wsgi:error] [pid 3470:tid 140503655892736] [client 192.168.1.237:34122] mod_wsgi (pid=3470): Target WSGI script '/var/www/mainapp/mainapp/mainapp.wsgi' cannot be loaded as Python module.
[Mon Dec 06 17:50:50.425676 2021] [wsgi:error] [pid 3470:tid 140503655892736] [client 192.168.1.237:34122] mod_wsgi (pid=3470): Exception occurred processing WSGI script '/var/www/mainapp/mainapp/mainapp.wsgi'.
[Mon Dec 06 17:50:50.425691 2021] [wsgi:error] [pid 3470:tid 140503655892736] [client 192.168.1.237:34122] Traceback (most recent call last):
[Mon Dec 06 17:50:50.425705 2021] [wsgi:error] [pid 3470:tid 140503655892736] [client 192.168.1.237:34122]   File "/var/www/mainapp/mainapp/mainapp.wsgi", line 8, in <module>
[Mon Dec 06 17:50:50.425728 2021] [wsgi:error] [pid 3470:tid 140503655892736] [client 192.168.1.237:34122]     with open(activate_this) as file_:
[Mon Dec 06 17:50:50.425743 2021] [wsgi:error] [pid 3470:tid 140503655892736] [client 192.168.1.237:34122] IOError: [Errno 13] Permission denied: '/home/server/.local/share/virtualenvs/mainapp-c6pGQO_3/bin/activate_this.py'
[Tue Dec 07 14:41:28.755748 2021] [wsgi:error] [pid 11815:tid 140503761520384] [client 192.168.1.237:44132] mod_wsgi (pid=11815): Target WSGI script '/var/www/mainapp/mainapp/mainapp.wsgi' cannot be loaded as Python module.
[Tue Dec 07 14:41:28.755830 2021] [wsgi:error] [pid 11815:tid 140503761520384] [client 192.168.1.237:44132] mod_wsgi (pid=11815): Exception occurred processing WSGI script '/var/www/mainapp/mainapp/mainapp.wsgi'.
[Tue Dec 07 14:41:28.755870 2021] [wsgi:error] [pid 11815:tid 140503761520384] [client 192.168.1.237:44132] Traceback (most recent call last):
[Tue Dec 07 14:41:28.755911 2021] [wsgi:error] [pid 11815:tid 140503761520384] [client 192.168.1.237:44132]   File "/var/www/mainapp/mainapp/mainapp.wsgi", line 8, in <module>
[Tue Dec 07 14:41:28.756020 2021] [wsgi:error] [pid 11815:tid 140503761520384] [client 192.168.1.237:44132]     with open(activate_this) as file_:
[Tue Dec 07 14:41:28.756064 2021] [wsgi:error] [pid 11815:tid 140503761520384] [client 192.168.1.237:44132] IOError: [Errno 13] Permission denied: '/home/server/.local/share/virtualenvs/mainapp-c6pGQO_3/bin/activate_this.py'
[Tue Dec 07 14:41:29.942452 2021] [wsgi:error] [pid 11815:tid 140503681070848] [client 192.168.1.237:44136] mod_wsgi (pid=11815): Target WSGI script '/var/www/mainapp/mainapp/mainapp.wsgi' cannot be loaded as Python module.
[Tue Dec 07 14:41:29.942546 2021] [wsgi:error] [pid 11815:tid 140503681070848] [client 192.168.1.237:44136] mod_wsgi (pid=11815): Exception occurred processing WSGI script '/var/www/mainapp/mainapp/mainapp.wsgi'.
[Tue Dec 07 14:41:29.942621 2021] [wsgi:error] [pid 11815:tid 140503681070848] [client 192.168.1.237:44136] Traceback (most recent call last):
[Tue Dec 07 14:41:29.942669 2021] [wsgi:error] [pid 11815:tid 140503681070848] [client 192.168.1.237:44136]   File "/var/www/mainapp/mainapp/mainapp.wsgi", line 8, in <module>
[Tue Dec 07 14:41:29.942741 2021] [wsgi:error] [pid 11815:tid 140503681070848] [client 192.168.1.237:44136]     with open(activate_this) as file_:
[Tue Dec 07 14:41:29.942791 2021] [wsgi:error] [pid 11815:tid 140503681070848] [client 192.168.1.237:44136] IOError: [Errno 13] Permission denied: '/home/server/.local/share/virtualenvs/mainapp-c6pGQO_3/bin/activate_this.py'
[Tue Dec 07 14:45:55.984834 2021] [wsgi:error] [pid 12064:tid 140146816845568] [client 192.168.1.237:44356] mod_wsgi (pid=12064): Target WSGI script '/var/www/mainapp/mainapp/mainapp.wsgi' cannot be loaded as Python module.
[Tue Dec 07 14:45:56.012639 2021] [wsgi:error] [pid 12064:tid 140146816845568] [client 192.168.1.237:44356] mod_wsgi (pid=12064): Exception occurred processing WSGI script '/var/www/mainapp/mainapp/mainapp.wsgi'.
[Tue Dec 07 14:45:56.012752 2021] [wsgi:error] [pid 12064:tid 140146816845568] [client 192.168.1.237:44356] Traceback (most recent call last):
[Tue Dec 07 14:45:56.012809 2021] [wsgi:error] [pid 12064:tid 140146816845568] [client 192.168.1.237:44356]   File "/var/www/mainapp/mainapp/mainapp.wsgi", line 8, in <module>
[Tue Dec 07 14:45:56.013006 2021] [wsgi:error] [pid 12064:tid 140146816845568] [client 192.168.1.237:44356]     with open(activate_this) as file_:
[Tue Dec 07 14:45:56.013066 2021] [wsgi:error] [pid 12064:tid 140146816845568] [client 192.168.1.237:44356] IOError: [Errno 13] Permission denied: '/home/server/.local/share/virtualenvs/mainapp-c6pGQO_3/bin/activate_this.py'
[Tue Dec 07 14:45:57.322264 2021] [wsgi:error] [pid 12064:tid 140146729023232] [client 192.168.1.237:44358] mod_wsgi (pid=12064): Target WSGI script '/var/www/mainapp/mainapp/mainapp.wsgi' cannot be loaded as Python module.
[Tue Dec 07 14:45:57.322404 2021] [wsgi:error] [pid 12064:tid 140146729023232] [client 192.168.1.237:44358] mod_wsgi (pid=12064): Exception occurred processing WSGI script '/var/www/mainapp/mainapp/mainapp.wsgi'.
[Tue Dec 07 14:45:57.322486 2021] [wsgi:error] [pid 12064:tid 140146729023232] [client 192.168.1.237:44358] Traceback (most recent call last):
[Tue Dec 07 14:45:57.322569 2021] [wsgi:error] [pid 12064:tid 140146729023232] [client 192.168.1.237:44358]   File "/var/www/mainapp/mainapp/mainapp.wsgi", line 8, in <module>
[Tue Dec 07 14:45:57.322693 2021] [wsgi:error] [pid 12064:tid 140146729023232] [client 192.168.1.237:44358]     with open(activate_this) as file_:
[Tue Dec 07 14:45:57.322753 2021] [wsgi:error] [pid 12064:tid 140146729023232] [client 192.168.1.237:44358] IOError: [Errno 13] Permission denied: '/home/server/.local/share/virtualenvs/mainapp-c6pGQO_3/bin/activate_this.py'
[Tue Dec 07 14:54:54.717813 2021] [wsgi:error] [pid 12064:tid 140146808452864] [client 192.168.1.237:44438] mod_wsgi (pid=12064): Target WSGI script '/var/www/mainapp/mainapp/mainapp.wsgi' cannot be loaded as Python module.
[Tue Dec 07 14:54:54.717921 2021] [wsgi:error] [pid 12064:tid 140146808452864] [client 192.168.1.237:44438] mod_wsgi (pid=12064): Exception occurred processing WSGI script '/var/www/mainapp/mainapp/mainapp.wsgi'.
[Tue Dec 07 14:54:54.717977 2021] [wsgi:error] [pid 12064:tid 140146808452864] [client 192.168.1.237:44438] Traceback (most recent call last):
[Tue Dec 07 14:54:54.718029 2021] [wsgi:error] [pid 12064:tid 140146808452864] [client 192.168.1.237:44438]   File "/var/www/mainapp/mainapp/mainapp.wsgi", line 8, in <module>
[Tue Dec 07 14:54:54.718103 2021] [wsgi:error] [pid 12064:tid 140146808452864] [client 192.168.1.237:44438]     with open(activate_this) as file_:
[Tue Dec 07 14:54:54.718155 2021] [wsgi:error] [pid 12064:tid 140146808452864] [client 192.168.1.237:44438] IOError: [Errno 13] Permission denied: '/home/server/.local/share/virtualenvs/mainapp-c6pGQO_3/bin/activate_this.py'
[Tue Dec 07 14:55:35.079104 2021] [wsgi:error] [pid 12306:tid 140650783700736] [client 192.168.1.237:44444] mod_wsgi (pid=12306): Target WSGI script '/var/www/mainapp/mainapp/mainapp.wsgi' cannot be loaded as Python module.
[Tue Dec 07 14:55:35.079156 2021] [wsgi:error] [pid 12306:tid 140650783700736] [client 192.168.1.237:44444] mod_wsgi (pid=12306): Exception occurred processing WSGI script '/var/www/mainapp/mainapp/mainapp.wsgi'.
[Tue Dec 07 14:55:35.079171 2021] [wsgi:error] [pid 12306:tid 140650783700736] [client 192.168.1.237:44444] Traceback (most recent call last):
[Tue Dec 07 14:55:35.079186 2021] [wsgi:error] [pid 12306:tid 140650783700736] [client 192.168.1.237:44444]   File "/var/www/mainapp/mainapp/mainapp.wsgi", line 8, in <module>
[Tue Dec 07 14:55:35.079222 2021] [wsgi:error] [pid 12306:tid 140650783700736] [client 192.168.1.237:44444]     with open(activate_this) as file_:
[Tue Dec 07 14:55:35.079238 2021] [wsgi:error] [pid 12306:tid 140650783700736] [client 192.168.1.237:44444] IOError: [Errno 13] Permission denied: '/home/server/.local/share/virtualenvs/mainapp-c6pGQO_3/bin/activate_this.py'
[Tue Dec 07 14:55:35.095068 2021] [wsgi:error] [pid 12306:tid 140650775308032] [client 192.168.1.237:44446] mod_wsgi (pid=12306): Target WSGI script '/var/www/mainapp/mainapp/mainapp.wsgi' cannot be loaded as Python module., referer: http://192.168.1.237/
[Tue Dec 07 14:55:35.095092 2021] [wsgi:error] [pid 12306:tid 140650775308032] [client 192.168.1.237:44446] mod_wsgi (pid=12306): Exception occurred processing WSGI script '/var/www/mainapp/mainapp/mainapp.wsgi'., referer: http://192.168.1.237/
[Tue Dec 07 14:55:35.095109 2021] [wsgi:error] [pid 12306:tid 140650775308032] [client 192.168.1.237:44446] Traceback (most recent call last):, referer: http://192.168.1.237/
[Tue Dec 07 14:55:35.095131 2021] [wsgi:error] [pid 12306:tid 140650775308032] [client 192.168.1.237:44446]   File "/var/www/mainapp/mainapp/mainapp.wsgi", line 8, in <module>, referer: http://192.168.1.237/
[Tue Dec 07 14:55:35.095161 2021] [wsgi:error] [pid 12306:tid 140650775308032] [client 192.168.1.237:44446]     with open(activate_this) as file_:, referer: http://192.168.1.237/
[Tue Dec 07 14:55:35.095182 2021] [wsgi:error] [pid 12306:tid 140650775308032] [client 192.168.1.237:44446] IOError: [Errno 13] Permission denied: '/home/server/.local/share/virtualenvs/mainapp-c6pGQO_3/bin/activate_this.py', referer: http://192.168.1.237/
[Tue Dec 07 14:55:39.955442 2021] [wsgi:error] [pid 12306:tid 140650758522624] [client 192.168.1.237:44448] mod_wsgi (pid=12306): Target WSGI script '/var/www/mainapp/mainapp/mainapp.wsgi' cannot be loaded as Python module.
[Tue Dec 07 14:55:39.955553 2021] [wsgi:error] [pid 12306:tid 140650758522624] [client 192.168.1.237:44448] mod_wsgi (pid=12306): Exception occurred processing WSGI script '/var/www/mainapp/mainapp/mainapp.wsgi'.
[Tue Dec 07 14:55:39.955610 2021] [wsgi:error] [pid 12306:tid 140650758522624] [client 192.168.1.237:44448] Traceback (most recent call last):
[Tue Dec 07 14:55:39.955663 2021] [wsgi:error] [pid 12306:tid 140650758522624] [client 192.168.1.237:44448]   File "/var/www/mainapp/mainapp/mainapp.wsgi", line 8, in <module>
[Tue Dec 07 14:55:39.955742 2021] [wsgi:error] [pid 12306:tid 140650758522624] [client 192.168.1.237:44448]     with open(activate_this) as file_:
[Tue Dec 07 14:55:39.955795 2021] [wsgi:error] [pid 12306:tid 140650758522624] [client 192.168.1.237:44448] IOError: [Errno 13] Permission denied: '/home/server/.local/share/virtualenvs/mainapp-c6pGQO_3/bin/activate_this.py'
[Tue Dec 07 14:55:40.614867 2021] [wsgi:error] [pid 12306:tid 140650766915328] [client 192.168.1.237:44450] mod_wsgi (pid=12306): Target WSGI script '/var/www/mainapp/mainapp/mainapp.wsgi' cannot be loaded as Python module.
[Tue Dec 07 14:55:40.614976 2021] [wsgi:error] [pid 12306:tid 140650766915328] [client 192.168.1.237:44450] mod_wsgi (pid=12306): Exception occurred processing WSGI script '/var/www/mainapp/mainapp/mainapp.wsgi'.
[Tue Dec 07 14:55:40.615032 2021] [wsgi:error] [pid 12306:tid 140650766915328] [client 192.168.1.237:44450] Traceback (most recent call last):
[Tue Dec 07 14:55:40.615104 2021] [wsgi:error] [pid 12306:tid 140650766915328] [client 192.168.1.237:44450]   File "/var/www/mainapp/mainapp/mainapp.wsgi", line 8, in <module>
[Tue Dec 07 14:55:40.615178 2021] [wsgi:error] [pid 12306:tid 140650766915328] [client 192.168.1.237:44450]     with open(activate_this) as file_:
[Tue Dec 07 14:55:40.615228 2021] [wsgi:error] [pid 12306:tid 140650766915328] [client 192.168.1.237:44450] IOError: [Errno 13] Permission denied: '/home/server/.local/share/virtualenvs/mainapp-c6pGQO_3/bin/activate_this.py'
[Tue Dec 07 14:55:42.747706 2021] [wsgi:error] [pid 12306:tid 140650750129920] [client 192.168.1.237:44456] mod_wsgi (pid=12306): Target WSGI script '/var/www/mainapp/mainapp/mainapp.wsgi' cannot be loaded as Python module.
[Tue Dec 07 14:55:42.747735 2021] [wsgi:error] [pid 12306:tid 140650750129920] [client 192.168.1.237:44456] mod_wsgi (pid=12306): Exception occurred processing WSGI script '/var/www/mainapp/mainapp/mainapp.wsgi'.
[Tue Dec 07 14:55:42.747750 2021] [wsgi:error] [pid 12306:tid 140650750129920] [client 192.168.1.237:44456] Traceback (most recent call last):
[Tue Dec 07 14:55:42.747763 2021] [wsgi:error] [pid 12306:tid 140650750129920] [client 192.168.1.237:44456]   File "/var/www/mainapp/mainapp/mainapp.wsgi", line 8, in <module>
[Tue Dec 07 14:55:42.747783 2021] [wsgi:error] [pid 12306:tid 140650750129920] [client 192.168.1.237:44456]     with open(activate_this) as file_:
[Tue Dec 07 14:55:42.747797 2021] [wsgi:error] [pid 12306:tid 140650750129920] [client 192.168.1.237:44456] IOError: [Errno 13] Permission denied: '/home/server/.local/share/virtualenvs/mainapp-c6pGQO_3/bin/activate_this.py'
